Workbook
Name __TDS2: '[3]Pre_XML'!$E$10
Name _TDS2: '[3]Pre_XML'!$E$10
Name A_C_NO: '[5]Account_NO_Co_code'!$A$2:$A$245
Name A_GEN1.AONo: '[3]GENERAL'!$AR$24
Name A_GEN1.AOType: '[3]GENERAL'!$AI$24
Name A_GEN1.AreaCode: '[3]GENERAL'!$AD$24
Name A_GEN1.AsseseeRepFlg: '[3]GENERAL'!$AN$31
Name A_GEN1.CityOrTownOrDistrict: '[3]GENERAL'!$C$18
Name A_GEN1.DateOFFormOrIncorp: '[3]GENERAL'!$AL$11
Name A_GEN1.DesigOfficerWardorCircle: '[3]GENERAL'!$C$24
Name A_GEN1.DomesticCompFlg: '[3]GENERAL'!$AQ$15
Name A_GEN1.EmailAddress: '[3]GENERAL'!$C$22
Name A_GEN1.FBTSec: '[3]GENERAL'!$AK$22
Name A_GEN1.IncomeTaxSec: '[3]GENERAL'!$AK$19
Name A_GEN1.LocalityOrArea: '[3]GENERAL'!$U$14
Name A_GEN1.NRI_PE: '[3]GENERAL'!$AR$30
Name A_GEN1.OrgOldName: '[3]GENERAL'!$U$6
Name A_GEN1.OrigRetFiledDate: '[3]GENERAL'!$AM$28
Name A_GEN1.PAN: '[3]GENERAL'!$AL$7
Name A_GEN1.PhoneNo: '[3]GENERAL'!$AD$22
Name A_GEN1.PinCode: '[3]GENERAL'!$AD$19
Name A_GEN1.RangeCode: '[3]GENERAL'!$AM$24
Name A_GEN1.ReceiptNo: '[3]GENERAL'!$U$28
Name A_GEN1.RepAddress: '[3]GENERAL'!$AC$34
Name A_GEN1.RepName: '[3]GENERAL'!$AC$33
Name A_GEN1.RepPAN: '[3]GENERAL'!$AC$35
Name A_GEN1.ResidenceName: '[3]GENERAL'!$U$10
Name A_GEN1.ResidenceNo: '[3]GENERAL'!$C$10
Name A_GEN1.ResidentialStatus: '[3]GENERAL'!$U$30
Name A_GEN1.ReturnType: '[3]GENERAL'!$V$26
Name A_GEN1.RoadOrStreet: '[3]GENERAL'!$C$14
Name A_GEN1.StateCode: '[3]GENERAL'!$U$18
Name A_GEN1.StatusOrCompanyType: '[3]GENERAL'!$AL$15
Name A_GEN1.STDcode: '[3]GENERAL'!$Y$22
Name A_GEN1.SurNameOrOrgName: '[3]GENERAL'!$C$6
Name A_GEN2.AudFrmName: '[3]GENERAL'!$W$40
Name A_GEN2.AudFrmPAN: '[3]GENERAL'!$AF$41
Name A_GEN2.AuditDate: '[3]GENERAL'!$N$42
Name A_GEN2.AuditorMemNo: '[3]GENERAL'!$R$39
Name A_GEN2.AuditorName: '[3]GENERAL'!$Y$38
Name A_GEN2.LiableSec44AAflg: '[3]GENERAL'!$AE$36
Name A_GEN2.LiableSec44ABflg: '[3]GENERAL'!$AO$37
Name AA10.DedFromUndertaking: '[3]10A'!$F$26
Name AA10.TotalDedUs10Sub: '[3]10A'!$H$27
Name AA10AA: '[3]Pre_XML'!$E$2
Name AAAA: '[6]IO'!$A$3:$A$657
Name adjtotloss.BusLossOthThanSpecLossCF9: '[3]CFL'!$F$12
Name adjtotloss.HPLossCF9: '[3]CFL'!$E$12
Name adjtotloss.LossFrmSpecBusCF9: '[3]CFL'!$G$12
Name adjtotloss.LTCGLossCF9: '[3]CFL'!$I$12
Name adjtotloss.OthSrcLossNotRaceHorseCF9: '[3]CFL'!$J$12
Name adjtotloss.OthSrcLossRaceHorseCF9: '[3]CFL'!$K$12
Name adjtotloss.STCGLossCF9: '[3]CFL'!$H$12
Name ANNEX1_TOTAL: '[7]ANNEX1'!$C$3:$C$23
Name ANNEX2_TOTAL: '[7]ANNEX2'!$C$3:$C$23
Name ANNEX3_TOTAL: '[7]ANNEX3'!$C$3:$C$23
Name ANNEX4_TOTAL: '[7]ANNEX4'!$C$3:$C$23
Name ANNEX5_TOTAL: '[7]ANNEX5'!$C$3:$C$23
Name ANNEX6_READONLY: '[7]PART-6'!$R$5:$R$7,'[7]PART-6'!$C$7,'[7]PART-6'!$F$7,'[7]PART-6'!$I$7,'[7]PART-6'!$L$7,'[7]PART-6'!$O$7,'[7]PART-6'!$L$13:$L$15,'[7]PART-6'!$C$15,'[7]PART-6'!$F$15,'[7]PART-6'!$I$15
Name asd: '[8]Index'!$C$5

Sheet 00_Cover
A1: Corporate Audit Report Pack
A2: Print-ready master format | A.Y. 2026-27 | Editable template
B5: Pack Contents | E5: Primary Use
B6: • Independent auditor's report format | E6: Statutory audit report master wording and signature block
B7: • Form 3CA + Form 3CD | E7: Tax audit report cover form in print-ready layout
B8: • Form 3CD clause-wise report | E8: Current official clause structure with editable response fields
B9: • 3CD annexures | E9: Clause-wise support tables for depreciation, disallowances, TDS, GST, loans, quantitative details and more
B10: • Financial statements | E10: Balance Sheet, Statement of Profit & Loss / Income & Expenditure, Cash Flow (where applicable)
B11: • Notes to accounts & annexures | E11: Editable note schedules and a separate narrative note bank
B12: • Legal sources sheet | E12: Official URLs used for current form alignment
B15: Key editable metadata
B16: Entity name | E16: KWIKTEAM SUPPORT SERVICES PRIVATE LIMITED_
B17: Financial year | E17: [01 Apr 2025 to 31 Mar 2026]_
B18: Report date | E18: 16/05/2026
B19: Firm name | E19: V J DESAI & CO. LLP
B20: PAN | E20: AABCK1234Z_
B21: TAN | E21: SRTK12345A_
B22: GSTIN | E22: 24AABCK1234Z1Z5_
B23: Assessment year | E23: [2026-27]_
B24: Signatory / Partner | E24: VIJAY J DESAI
B25: Membership
B26: FRN
B27: UDIN

Sheet 01_Control
A2: Control Sheet
A3: Central editable fields | Corporate Entity
A5: Entity Details
B6: Entity name | F6: KWIKTEAM SUPPORT SERVICES PRIVATE LIMITED
B7: Registered office / address | F7: SURAT, GUJARAT
B8: P.A. Number (PAN) | F8: AABCK1234Z
B9: T.A. Number (TAN) | F9: SRTK12345A
B10: GST No. | F10: 24AABCK1234Z1Z5
B11: Entity type | F11: Corporate Entity
B12: Nature of business | F12: IT Support Services
B13: Previous year | F13: 01 Apr 2025 to 31 Mar 2026
B14: Assessment year | F14: 2026-27
B15: Balance sheet date | F15: 31st March, 2026 | G15: ____
B16: Comparative year-end | F16: 31st March, 2025 | G16: ____
B17: Rounding off / units | F17: Amount in Rs. / Lakhs / Hundreds / Thousands
A18: Audit Report Sign-off
B19: Audit firm name | F19: V J DESAI & CO. LLP
B20: Signing partner / proprietor | F20: VIJAY J DESAI
B21: Firm registration no. | F21: 123456W
B22: Membership no. | F22: M12345
B23: UDIN | F23: 26012345AAAAAA1234
B24: Report date | F24: 16/05/2026
B25: Place | F25: SURAT
B26: Board / partner signatories | F26: 16/05/2026
B28: 1. Keep styles, margins and print areas unchanged; replace only figures and editable narrative blocks.
B29: 2. Populate note schedules first; linked primary statements can then be refreshed / reviewed.
B30: 3. Review signatory names, UDIN, report date, comparative dates and law-specific paragraphs before issue.
B31: 4. Form 3CD sheets are arranged clause-wise with annexure references for fast review and population.

Sheet 02_Index
A1: Workbook Index
A2: Navigation map and recommended print sequence
A4: Seq. | B4: Sheet | C4: Category | D4: Purpose | E4: Go
A5: 1 | B5: 00_Cover | C5: Admin / Navigation | D5: Editable working / presentation sheet | E5: Open
A6: 2 | B6: 01_Control | C6: Admin / Navigation | D6: Editable working / presentation sheet | E6: Open
A7: 3 | B7: BS | C7: Financial Statements | D7: Editable working / presentation sheet | E7: Open
A8: 4 | B8: PL | C8: Financial Statements | D8: Editable working / presentation sheet | E8: Open
A9: 5 | B9: CFS | C9: Financial Statements | D9: Editable working / presentation sheet | E9: Open
A10: 6 | B10: Note BS-Liab | C10: Financial Statements | D10: Editable working / presentation sheet | E10: Open
A11: 7 | B11: FA | C11: Financial Statements | D11: Editable working / presentation sheet | E11: Open
A12: 8 | B12: Note BS-Asset | C12: Financial Statements | D12: Editable working / presentation sheet | E12: Open
A13: 9 | B13: Note PL | C13: Financial Statements | D13: Editable working / presentation sheet | E13: Open
A14: 10 | B14: 31-36 | C14: Financial Statements | D14: Editable working / presentation sheet | E14: Open
A15: 11 | B15: 37-47 | C15: Financial Statements | D15: Editable working / presentation sheet | E15: Open
A16: 12 | B16: FA - IT Act | C16: Financial Statements | D16: Editable working / presentation sheet | E16: Open
... A40: 36 | B40: 99_Legal_Sources | C40: Reference | D40: Editable working / presentation sheet | E40: Open
A42: Recommended print sequence: Cover → Statutory report → Tax audit report → Form 3CD → 3CD annexures → Financial statements → Notes to accounts.

Sheet BS
B2: KWIKTEAM SUPPORT SERVICES PRIVATE LIMITED
B4: Balance Sheet as at 31st March, 2025
E5: (Amount in Rs. `000)
B6: Particulars | D6: Note No. | E6: As at | F6: As at
E7: 31st March, 2026 | F7: 31st March, 2025
B9: I EQUITY AND LIABILITIES
B11: (1) Shareholders' funds
B12: (a) Share capital | D12: 2 | E12: 100000 | F12: 100000
B13: (b) Reserves and surplus | D13: 3 | E13: 536933 | F13: 0
B15: (2) Share application money pending allotment | E15: 0 | F15: 0
B17: (3) Non-Current liabilities
B18: (a) Long-term borrowings | E18: 0 | F18: 0
B19: (b) Deferred tax liabilities (Net) | E19: 0 | F19: 0
B20: (c) Other Long term liabilities | E20: 0 | F20: 0
B21: (d) Long-term provisions | E21: 0 | F21: 0
B23: (4) Current liabilities
B24: (a) Short-term borrowings | E24: 0 | F24: 0
B25: (b) Trade payables | D25: 8
B26: (i) Micro and Small Enterprises | E26: ='Note BS-Liab'!G106 -> 0 | F26: ='Note BS-Liab'!H106 -> 0
B27: (ii) Others | E27: 500000 | F27: 400000
B28: (c) Other current liabilities | D28: 9 | E28: 200000 | F28: 150000
B29: (d) Short-term provisions | E29: 0 | F29: 0
C31: TOTAL EQUITY AND LIABILITIES | E31: =SUM(E10:E30) -> 0 | F31: =SUM(F10:F30) -> 0
B33: II ASSETS
B35: (1) Non-Current Assets
B36: (a) Property, Plant & Equipment and Intangible Assets
B37: (i)Property, plant and equipment and Intangible Assets | D37: 10 | E37: 600000 | F37: 700000
B38: (ii) Intangible assets
B39: (iii) Capital work-in-Progress
B40: (b) Non-current investments | E40: 0 | F40: 0
B41: (c) Deferred tax assets (Net) | E41: 0 | F41: 0
B42: (d) Long-term loans and advances | E42: 0 | F42: 0
B43: (e) Other non-current Assets | E43: 0 | F43: 0
B45: (2) Current assets
B46: (a) Current investments | E46: 0 | F46: 0
B47: (b) Inventories | D47: 14 | E47: 200000 | F47: 150000
B48: (c) Trade receivables | D48: 15 | E48: 400000 | F48: 300000
B49: (d) Cash and bank equivalents | D49: 16 | E49: 136641 | F49: 100000
B50: (e) Short-term loans and advances | E50: 0 | F50: 0
B51: (f) Other current assets | E51: 0 | F51: 0
...

Sheet PL
B2: KWIKTEAM SUPPORT SERVICES PRIVATE LIMITED
B4: Statement of Profit & Loss Account for the year ended as on 31st March, 2025 | P4: =1261304 -> 1261304 | S4: 15206818
G5: (Amount in Rs. `000) | P5: =P4/BS!E12 -> #DIV/0! | S5: =(S4-H15-H16)/S4 -> 1
B6: Particulars | F6: Note No. | G6: For the year ended 31st March, 2026 | H6: For the year ended 31st March, 2025 | P6: =P5*10 -> #DIV/0!
R7: 23366246
B9: I. | C9: Revenue from operations | G9: 2000000 | H9: 1800000 | P9: =H9*1% -> 0
B10: II. | C10: Other income | G10: 50000 | H10: 40000
B11: III. | C11: Total Income (I+II) | G11: =SUM(G9:G10) -> 0 | H11: =SUM(H9:H10) -> 0
B13: IV. | C13: Expenses
C14: Cost of materials consumed | G14: 0 | H14: 0
C15: Purchases of Stock-in-Trade | G15: 0 | H15: 0 | P15: =J15/H9 -> #DIV/0! | R15: Cost of good sold | T15: 1295973.1
C16: Changes in inventories of finished goods, Work-in-progress and Stock-in-Trade | G16: ='Note PL'!F47 -> 0 | H16: ='Note PL'!G47 -> 0 | X16: Opex in V1 | Y16: 4874197.8
C17: Employee benefits expense | G17: 800000 | H17: 750000 | R17: =3520756 -> 3520756 | S17: =G17-R17 -> -3520756 | X17: Change in Opex | Y17: =Y16-G20 -> 4874197.8
C18: Finance Costs | G18: 50000 | H18: 45000
C19: Depreciation & Amortisation Expenses | G19: 100000 | H19: 100000 | P19: =SUM(G17:G20) -> 0 | U19: 8504233.8 | X19: Tfrd to Employee com
C20: Other expenses | G20: 563067 | H20: 545000 | P20: 6724162 | R20: 4874197.8 | S20: =G20-R20 -> -4874197.8 | U20: =U19-G20-G19-G17 -> 8504233.8 | X20: Remaining change
C21: Total Expenses | G21: 0 | H21: 0 | R21: 4821819 | S21: =G23-R21 -> -4821819 | X21: Prepaid ins | Y21: 203971.09
U22: =U20-#REF! -> #REF! | X22: Remaining change in Ins
B23: V. | C23: Profit before exceptional and extraordinary items and tax | G23: =G11-G21 -> 0 | H23: =H11-H21 -> 0 | P23: =H23*5% -> 0 | Q23: PM | R23: 23178517 | S23: =S21*26% -> -1253672.9
C24: (III-IV)
B25: VI. | C25: Exceptional items
B26: VII. | C26: Profit before extraordinary items and tax (V-VI)
B27: VIII. | C27: Extraordinary items | G27: 0 | H27: 0
B28: IX. | C28: Profit before tax (VII-VIII) | G28: =G23-G27 -> 0 | H28: =H23-H27 -> 0 | R28: =G21-R23 -> -23178517
B29: X. | C29: Tax expense: | S29: 1247640 | T29: =G30-S29 -> -1247640
C30: (1) Current tax | G30: 0 | H30: 0 | P30: =482100-G23 -> 482100
C31: (2) Deferred tax | G31: 0 | H31: 0 | P31: =P30*26% -> 125346
B32: XI. | C32: Profit (loss) for period from continuing operations | S32: =S21-T29 -> -3574179
C33: (VII-VIII)
B34: XII. | C34: Profit (loss) for period from discontinuing operations
B35: XIII. | C35: Tax expense of discontinuing operations
B36: XIV. | C36: Profit (loss) from discontinuing operations (after tax)
C37: (XII-XIII)
B38: XV. | C38: Profit / (Loss) for the period (XI+XIV) | G38: =G28-G30+G31 -> 0 | H38: =H28-SUM(H30:H31) -> 0
C40: Earnings per equity share ;
C41: (1) Basic | G41: =IFERROR(G38/'Note BS-Liab'!G21,0) -> 0 | H41: =IFERROR(H38/'Note BS-Liab'!H21,0) -> 0 | P41: =G38/BS!E12*10 -> #DIV/0!
C42: (2) Diluted
C44: The accompanying notes form an integral part of the financial statements.
C46: As per our Audit Report of even date
C48: =BS!B59 -> For [STATUTORY AUDITOR NAME] | F48: For and on behalf of the Board of Directors of
...

Sheet CFS
B1: KWIKTEAM SUPPORT SERVICES PRIVATE LIMITED
B3: Cash Flow Statement for the year ended [31st March, 2025]
H4: (Amount in Rs. `000)
B5: Particulars | H5: As at 31st March, 2026 | I5: As at 31st March, 2025
B8: A. | C8: Cash flows from operating activities
C9: Net profit before tax | H9: =PL!G23 -> 0 | I9: =PL!H23 -> 0
C10: Adjustments for:
C11: Depreciation expense | H11: =PL!G19 -> 0 | I11: =PL!H19 -> 0
C12: Interest income
C13: Profit on sale of assets
C14: Interest expense
C16: Operating profit before working capital changes | H16: =SUM(H9:H14) -> 0 | I16: =SUM(I9:I14) -> 0
C17: Changes in working capital:
C18: Trade payables | H18: =+'Note BS-Liab'!G75-'Note BS-Liab'!H75 -> 0 | I18: 0
C19: Other current liabilities | H19: =SUM('Note BS-Liab'!G140:G143)-SUM('Note BS-Liab'!H140:H143) -> 0 | I19: 0
C20: Inventories | H20: =BS!F47-BS!E47 -> 0 | I20: 0
C21: Trade receivables | H21: =BS!F48-BS!E48 -> 0 | I21: 0
C22: Short term provision
C23: Other current assets | H23: ='Note BS-Asset'!H100-'Note BS-Asset'!G100+'Note BS-Asset'!H35-'Note BS-Asset'!G35 -> 0 | I23: 0
C24: Cash generated from operations | H24: =SUM(H16:H23) -> 0 | I24: =SUM(I16:I23) -> 0
C25: Income tax paid | H25: 0 | I25: 0
C26: Net cash generated from operating activities (A) | H26: =H24+H25 -> 0 | I26: =I24+I25 -> 0
B28: B. | C28: Cash flows from investing activities
C29: Purchase of property, plant & equipments | H29: =-FA!E22 -> 0 | I29: 0
C30: Interest Income
C31: Net cash used in investing activities (B) | H31: =SUM(H29:H30) -> 0 | I31: =SUM(I29:I30) -> 0
B33: C. | C33: Cash flows from financing activities
C34: Proceeds from issue of share capital | H34: 0 | I34: 0
C35: Proceeds / Repayment of long-term Borrowings
C36: Payment of Other Loan term Liabilities
C37: Interest Paid
C38: Net cash used in financing activities (C) | H38: =SUM(H34:H37) -> 0 | I38: =SUM(I34:I37) -> 0
C40: Net increase in cash and cash equivalents (A+B+C) | H40: =H26+H31+H38 -> 0 | I40: =I26+I31+I38 -> 0
C41: Cash and cash equivalents at the beginning of period | H41: =I42 -> 0 | I41: 0
C42: Cash and cash equivalents at the end of period | H42: =SUM(H40:H41) -> 0 | I42: =SUM(I40:I41) -> 0
C45: Notes to cash flow statement
C46: The above cash flow statement has been prepared in accordance with the 'Indirect method' as set out in Accounting Standard - 3 on 'Cash Flow Statements'.
C47: The accompanying notes form an integral part of the financial statements.
C49: This is the Cash Flow Statement referred to in our report of even date
C51: =BS!B59 -> For [STATUTORY AUDITOR NAME] | G51: For and on behalf of the Board of Directors of
...

Sheet Note BS-Liab
A2: KWIKTEAM SUPPORT SERVICES PRIVATE LIMITED
A4: Schedules to Balance Sheet as at 31st March, 2025
A5: =+BS!D12 -> 2 | B5: Share capital | H5: =+CFS!H4 -> (Amount in Rs. `000)
B6: Particulars | G6: As at 31st March, 2026 | H6: As at 31st March, 2025
B7: Authorised shares
B8: ___ equity shares of face value of Rs.__ each | G8: 0 | H8: 0
B10: Issued, subscribed and fully paid up shares
B11: ___ equity shares of face value of Rs.__ each | G11: 0 | H11: 0
G12: =SUM(G11) -> 0 | H12: =SUM(H11) -> 0
A14: (a) | B14: Reconciliation of the shares outstanding at the beginning and at the end of the reporting period
B16: Particulars | G16: =+G6 -> As at 31st March, 2026 | H16: =+H6 -> As at 31st March, 2026
B17: Equity shares | G17: Number | H17: Amount
B18: Opening balance at the beginning of the year | G18: 0 | H18: 0
B19: Movement during the year | G19: 0 | H19: 0
B21: Outstanding at the end of the year | G21: =SUM(G18:G20) -> 0 | H21: =SUM(H18:H20) -> 0
A23: (b) | B23: Particulars of shareholders holding more than 5% shares
B24: Shareholders Name | E24: =+G16 -> As at 31st March, 2026 | G24: =+H16 -> As at 31st March, 2026
E25: No. of shares | F25: % of holding | G25: No. of shares | H25: % of holding
E26: 0 | F26: 0 | G26: 0 | H26: 0
E27: 0 | F27: 0 | G27: 0 | H27: 0
A32: (c) | B32: Promoters Shareholding
B33: Promoter name | D33: As at March 31, 2024 | F33: As at March 31, 2023 | H33: % Change during the year
D34: No. of Shares | E34: % of Total Shares | F34: No. of Shares | G34: % of Total Shares
H35: =E35-G35 -> 0
B38: Total | D38: =SUM(D35:D37) -> 0 | E38: =SUM(E35:E37) -> 0 | F38: =SUM(F35:F37) -> 0 | G38: =SUM(G35:G37) -> 0 | H38: =SUM(H35:H37) -> 0
A40: =BS!D13 -> 3 | B40: Reserves and surplus | H40: =+H5 -> (Amount in Rs. `000)
B41: Particulars | G41: =+G16 -> As at 31st March, 2026 | H41: =+H16 -> As at 31st March, 2026
B42: 1. General Reserve | G42: 0 | H42: 0
B43: 2. Share Premium | G43: 0 | H43: 0
F45: [a] | G45: =SUM(G42:G44) -> 0 | H45: =SUM(H42:H44) -> 0
B47: Surplus in the Statement of Profit and Loss
B48: Opening balance | G48: =H54 -> 0 | H48: 0
B49: Add/(Less) : Profit for the year | G49: =PL!G38 -> 0 | H49: =PL!H38 -> 0
B50: Add/(Less) : Adj. for Deferered tax | G50: 0 | H50: 0
B51: Add/(Less) : Excess/short provi. for Income tax | G51: 0 | H51: 0
F52: [b] | G52: =SUM(G48:G51) -> 0 | H52: =SUM(H48:H51) -> 0
B54: Total | F54: [a] + [b] | G54: =+G45+G52 -> 0 | H54: =+H45+H52 -> 0
A57: =+A2 -> [NAME OF THE COMPANY]
A59: =+A4 -> Schedules to Balance Sheet as at 31st March, 2026
A60: =BS!D18 | B60: Long-term borrowings
...

Sheet FA
A2: =BS!B2 -> [NAME OF THE COMPANY]
A4: =BS!D37 -> 10 | B4: Property, Plant and Equipment and Intangible Assets
B5: For the year 2026-27 | M5: =+BS!E5 -> (Amount in Rs. `000)
B6: Particulars | C6: Usefull life (years) | D6: Gross block | H6: Accumulated depreciation | L6: Net block
D7: As at 1 April 2025 | E7: Additions during the year | F7: Disposals during the year | G7: =+'Note BS-Liab'!G6 -> As at 31st March, 2026 | H7: As at 1 April 2025 | I7: Additions during the year | J7: Disposals during the year | K7: =+G7 -> As at 31st March, 2026 | L7: =+K7 -> As at 31st March, 2026 | M7: As at 31st March, 2026
B9: Property, Plant and Equipment
B10: Land
B11: Factory Building | C11: 30 | D11: 0 | E11: 0 | F11: 0 | G11: =D11+E11-F11 -> 0 | H11: 0 | I11: 0 | J11: 0 | K11: =H11+I11-J11 -> 0 | L11: =+G11-K11 -> 0 | M11: =D11-H11 -> 0
B12: Plant & Machinery | C12: 15 | D12: 0 | E12: 0 | F12: 0 | G12: =D12+E12-F12 -> 0 | H12: 0 | I12: 0 | J12: 0 | K12: =H12+I12-J12 -> 0 | L12: =+G12-K12 -> 0 | M12: =D12-H12 -> 0
B13: Electric Equipments | C13: 10 | D13: 0 | E13: 0 | F13: 0 | G13: =D13+E13-F13 -> 0 | H13: 0 | I13: 0 | J13: 0 | K13: =H13+I13-J13 -> 0 | L13: =+G13-K13 -> 0 | M13: =D13-H13 -> 0
B14: Computers | C14: 3 | D14: 0 | E14: 0 | F14: 0 | G14: =D14+E14-F14 -> 0 | H14: 0 | I14: 0 | J14: 0 | K14: =H14+I14 -> 0 | L14: =G14-K14 -> 0 | M14: =D14-H14 -> 0
B15: Office equipment | C15: 5 | D15: 0 | E15: 0 | F15: 0 | G15: =D15+E15-F15 -> 0 | H15: 0 | I15: 0 | J15: 0 | K15: =H15+I15 -> 0 | L15: =G15-K15 -> 0 | M15: =D15-H15 -> 0
B16: Furniture and fixtures | C16: 10 | D16: 0 | E16: 0 | F16: 0 | G16: =D16+E16-F16 -> 0 | H16: 0 | I16: 0 | J16: 0 | K16: =H16+I16 -> 0 | L16: =G16-K16 -> 0 | M16: =D16-H16 -> 0
B17: Vehicles | C17: 8 | D17: 0 | E17: 0 | F17: 0 | G17: =D17+E17-F17 -> 0 | H17: 0 | I17: 0 | J17: 0 | K17: =H17+I17 -> 0 | L17: =G17-K17 -> 0 | M17: =D17-H17 -> 0
B19: Intangible Assets
B20: Software | C20: 10 | D20: 0 | E20: 0 | F20: 0 | G20: =D20+E20-F20 -> 0 | H20: 0 | I20: 0 | J20: 0 | K20: =H20+I20 -> 0 | L20: =G20-K20 -> 0 | M20: =D20-H20 -> 0
B22: Total - Current year | D22: =SUM(D10:D21) -> 0 | E22: =SUM(E10:E21) -> 0 | F22: =SUM(F10:F21) -> 0 | G22: =SUM(G10:G21) -> 0 | H22: =SUM(H10:H21) -> 0 | I22: =SUM(I10:I21) -> 0 | J22: =SUM(J10:J21) -> 0 | K22: =SUM(K10:K21) -> 0 | ... M22: =SUM(M10:M21) -> 0
B23: Total - Previous year | D23: 0 | E23: 0 | F23: 0 | G23: 0 | H23: 0 | I23: 0 | J23: 0 | K23: 0 | L23: 0 | M23: 0
B25: Notes:
B26: 2. The Company has not revalued its Property, Plant and Equipment during the year ended March 31, 2026 and March 31, 2026.
B205: Dividend distribution tax

Sheet Note BS-Asset
A1: =BS!B2 -> [NAME OF THE COMPANY]
A3: Schedules to Balance Sheet as at 31st March, 2025
A5: =BS!D40 | B5: Non-current investments | H5: =+BS!E5 -> (Amount in Rs. `000)
B6: Particulars | G6: As at | H6: As at
B7: (Also disclose aggregate amount of Quoted and Unquoted investments) | G7: =+BS!E7 -> 31st March, 2026 | H7: =+BS!F7 -> 31st March, 2026
B8: (a) Investment property | G8: 0 | H8: 0
B9: (b) Investments in Equity Instruments | G9: 0 | H9: 0
B10: (c) Other non-current investments (specify nature) | G10: 0 | H10: 0
B12: Total | G12: =SUM(G8:G11) -> 0 | H12: =SUM(H8:H11) -> 0
A14: =BS!D41 | B14: Deferred tax assets | H14: (Amount in ` hundreds)
B15: Particulars | G15: =+'Note BS-Liab'!G6 -> As at 31st March, 2026 | H15: =+'Note BS-Liab'!H6 -> As at 31st March, 2026 | K15: or | L15: As at
B17: Excess of depreciation on fixed assets in accounts over depreciation as per Income Tax Act, 1961 | G17: 0 | H17: 0
B19: Total | G19: =SUM(G16:G17) -> 0 | H19: =SUM(H16:H17) -> 0
A21: =BS!D42 | B21: Long-term loans and advances
B22: Particulars | G22: =+G15 -> As at 31st March, 2026 | H22: =+H15 -> As at 31st March, 2026
B23: (b) Capital Advances | G23: 0 | H23: 0
B24: (c) Loans and advances to related parties (giving details thereof) | G24: 0 | H24: 0
B25: (d) Other loans and advances (specify nature) | G25: 0 | H25: 0
B27: Total | G27: =SUM(G23:G26) -> 0 | H27: =SUM(H23:H26) -> 0
A30: =BS!D43 | B30: Other non-current assets
B31: Particulars | G31: =+G22 -> As at 31st March, 2026 | H31: =+H22 -> As at 31st March, 2026
B32: Security Deposits | G32: 0 | H32: 0
B33: Others | G33: 0 | H33: 0
B35: Total | G35: =SUM(G32:G33) -> 0 | H35: =SUM(H32:H33) -> 0
A37: =BS!D46 | B37: Current Investment
B38: Particulars | G38: As at | H38: As at
B39: (Also disclose aggregate amount of Quoted and Unquoted investments) | G39: =+G7 -> 31st March, 2026 | H39: =+H7 -> 31st March, 2026
B40: Secured / Unsecured - specify
B41: (a) Investments in Equity Instruments | G41: 0 | H41: 0
B42: (b) Other investments (specify nature) | G42: 0 | H42: 0
B44: Total | G44: =SUM(G38:G42) -> 0 | H44: =SUM(H38:H42) -> 0
A46: =BS!D47 -> 14 | B46: Inventories
B47: Particulars | G47: =+G31 -> As at 31st March, 2026 | H47: =+H31 -> As at 31st March, 2026
B48: Stock-in-trade | G48: ='Note PL'!F39 -> 0 | H48: ='Note PL'!G39 -> 0
B50: Total | G50: =SUM(G45:G48) -> 0 | H50: =SUM(H45:H48) -> 0
A53: =+A1 -> [NAME OF THE COMPANY]
A55: =+A3 -> Schedules to Balance Sheet as at 31st March, 2026
A57: =BS!D48 -> 15 | B57: Trade Receivables | H57: (Amount in ` hundreds)
B58: Particulars | G58: =+G47 -> As at 31st March, 2026 | H58: =+H47 -> As at 31st March, 2026
B59: Outstanding for a period exceeding six months from the date they are due for payment | G59: 0 | H59: 0
...

Sheet Note PL
A1: =BS!B2 -> [NAME OF THE COMPANY]
J2: =0.01*PL!G9 -> 0 | K2: =0.01*PL!H9 -> 0
A3: Schedules to Profit & Loss A/c. for Financial year 20__ - __
A5: =PL!F9 | B5: Revenue from operations | G5: =+BS!E5 -> (Amount in Rs. `000)
B6: Particulars | F6: For the year ended 31st March, 2026 | G6: For the year ended 31st March, 2025
B7: Sale of products (Net off sales return) | F7: 0 | G7: 0 | I7: DON’T SHOW VAT, GST ETC. HERE. SHOW NET REVENUE
B8: Sale of services | F8: 0 | G8: 0
B9: Commission income | F9: 0 | G9: 0
B11: Total | F11: =SUM(F7:F10) -> 0 | G11: =SUM(G7:G10) -> 0
A13: =PL!F10 | B13: Other Income
B14: Particulars | F14: =+F6 -> For the year ended 31st March, 2026 | G14: =+G6 -> For the year ended 31st March, 2026
B15: Interest income | F15: 0 | G15: 0
B16: Gain on Forex fluctuation (Net) | F16: 0 | G16: 0
B17: Miscellaneous income | F17: 0 | G17: 0
B19: Total | F19: =SUM(F15:F18) -> 0 | G19: =SUM(G15:G18) -> 0
A21: =PL!F10 | B21: Cost of materials consumed
B22: Particulars | F22: =+F14 -> For the year ended 31st March, 2026 | G22: =+G14 -> For the year ended 31st March, 2026
B23: Raw Material Consumed
B24: Opening Stock | F24: 0 | G24: 0
B25: Purchases | F25: 0 | G25: 0
B26: Less: Closing Stock | F26: 0 | G26: 0
B28: Total | F28: =+F24+F25-F26 -> 0 | G28: =+G24+G25-G26 -> 0
A30: =PL!F15 | B30: Purchase of stock-in-trade
B31: Particulars | F31: =+F14 -> For the year ended 31st March, 2026 | G31: =+G14 -> For the year ended 31st March, 2026
B32: Traded goods | F32: 0 | G32: 0
B34: Total | F34: =SUM(F32:F33) -> 0 | G34: =SUM(G32:G33) -> 0
A36: =PL!F16 | B36: Changes in inventories
B37: Particulars | F37: =+F31 -> For the year ended 31st March, 2026 | G37: =+G31 -> For the year ended 31st March, 2026
B38: Inventories at the end of the year
B39: Finished goods | F39: 0 | G39: 0 | J39: =0.0015*100 -> 0.15
F41: =SUM(F39:F40) -> 0 | G41: =SUM(G39:G40) -> 0
B42: Inventories at the beginning of the year
B43: Finished goods | F43: =G39 -> 0 | G43: 0
F45: =SUM(F43:F44) -> 0 | G45: =SUM(G43:G44) -> 0
B47: Net (increase)/decrease in inventory | F47: =F45-F41 -> 0 | G47: =G45-G41 -> 0
A49: =PL!F17 | B49: Employee benefits expense
B50: Particulars | F50: =+F37 -> For the year ended 31st March, 2026 | G50: =+G37 -> For the year ended 31st March, 2026
B51: Salaries and wages | F51: 0 | G51: 0
B52: Remuneration to directors | F52: 0 | G52: 0 | H52: If TDS is deducted u/s 192B
B53: Contribution to provident and other funds | F53: 0 | G53: 0
...

Sheet Notes other
B1: =BS!B2 -> [NAME OF THE COMPANY]
B3: Summary of other explanatory notes for the year ended 31st March, 2026
C5: Earnings in foreign currency
C6: Particulars | E6: 31/03/2026 | G6: 31/03/2026
E7: ='Note PL'!F9 -> 0 | G7: 0
C9: Expenditure in foreign currency
C10: Particulars | E10: 31/03/2026 | G10: 31/03/2026
E11: ='Note PL'!F13 -> 0 | G11: 0
C13: C. I. F. Value of Imports | F13: xx | G13: xx
C16: Employee Benefits
B18: No. | C18: Particulars | F18: Current Year | G18: Prev. Year
B19: (i) | C19: Wages and Salaries
B20: (ii) | C20: Paid Annual Leave
B21: (iii) | C21: Profit Sharing and Bonus payments
B22: (iv) | C22: Perquisites - Medical Care, Housing, Cars
B23: (v) | C23: Defined Contribution Plans
C24: Total
C25: Of this, Payments to KMP
C28: Related party disclosure
C29: a) List of related parties and relationships
C31: Description of relationship | D31: Names of related parties
C32: Key management personnel | D32: Ms. A, Director
D33: Ms. B, Director
D34: Mr. C, Director
C36: Other | D36: Ms. A,
C38: b) Details of related party transactions in the ordinary course of the business
C40: Particulars | D40: Nature of transactions | F40: 31st March, 2026 | G40: 31st March, 2025
C54: In accordance with AS 18, disclosures in respect of transactions with identified related parties are given only for such period during which the relationship existed. Related party relationships as given above are as identified by the Company and relied upon by the auditors.

Sheet Notes other2
B1: =BS!B2 -> [NAME OF THE COMPANY]
B3: Summary of other explanatory notes for the year ended 31st March, 2026
C5: RATIO
B7: No. | C7: Particulars | D7: Numerator | E7: Amount (Rs.) | F7: Current Year 2026-27 | G7: Previous Year 2025-26 | H7: Variance
D8: Denominator
B9: 1 | C9: Current Ratio (In times) | D9: Total Current Assets | E9: 0 | F9: =+IFERROR(E9/E10,0) -> 0 | G9: 0 | H9: =+IFERROR(((F9-G9)/G9),0) -> 0
D10: Total Current Liabilities | E10: 0
B12: 2 | C12: Debt-Equity Ratio (In times) | D12: Total Debt | E12: 0 | F12: =+IFERROR(E12/E13,0) -> 0 | G12: 0 | H12: =IFERROR(((F12-G12)/G12),0) -> 0
D13: Shareholder'S Equity | E13: 0
B15: 3 | C15: =N15 -> Debt Service Coverage Ratio (In Times) | D15: Earning Available for Debt Service | E15: 0 | F15: =+IF(ISNUMBER(E15/E16),E15/E16,"N.A.") -> N.A. | G15: 0 | H15: =+IFERROR(((F15-G15)/G15),0) -> 0 | N15: Debt Service Coverage Ratio (In Times)
D16: Debt Service | E16: 0
E18: 0
B19: 4 | C19: Return On Equity Ratio (In % ) | D19: Net Profit After Tax | E19: 0 | F19: =+IFERROR(E19/E20,0) -> 0 | G19: 0 | H19: =+IFERROR(((F19-G19)/G19),0) -> 0 | N19: Return On Equity Ratio (In % )
D20: Averages Shareholders Equity | E20: 0
B23: 5 | C23: Inventory Turnover Ratio (In Times) | D23: Cost Of Goods Sold | E23: 0 | F23: =+IF(ISNUMBER(E23/E24),E23/E24,"N.A.") -> N.A. | G23: 0 | H23: =+IFERROR(((F23-G23)/G23),0) -> 0 | N23: Inventory Turnover Ratio (In Times)
D24: Average Inventories | E24: 0 | K24: =PROPER(C24)
K26: =PROPER(C26)
B27: 6 | C27: Trade Receivables Turnover Ratio (In Times) | D27: Revenue from Operations | E27: 0 | F27: =+IF(ISNUMBER(E27/E28),E27/E28,"N.A.") -> N.A. | G27: 0 | H27: =+IFERROR(((F27-G27)/G27),0) -> 0 | N27: Trade Receivables Turnover Ratio (In Times)
D28: Average Trade Receivables | E28: 0
B31: 7 | C31: Trade Payables Turnover Ratio (In Times) | D31: Net Credit Purchases | E31: 0 | F31: =+IF(ISNUMBER(E31/E32),E31/E32,"N.A.") -> N.A. | G31: 0 | H31: =+IFERROR(((F31-G31)/G31),0) -> 0 | N31: Trade Payables Turnover Ratio (In Times)
D32: Average Trade Payables | E32: 0
B35: 8 | C35: Net Capital Turnover Ratio (In Times) | D35: Revenue from Operations | E35: 0 | F35: =+IFERROR(E35/E36,0) -> 0 | G35: 0 | H35: =+IFERROR(((F35-G35)/G35),0) -> 0 | N35: Net Capital Turnover Ratio (In Times)
D36: Working Capital | E36: 0
B38: 9 | C38: Net Profit Ratio (In % ) | D38: Net Profit After Tax | E38: 0 | F38: =+IFERROR(E38/E39,0) -> 0 | G38: 0 | H38: =+IFERROR(((F38-G38)/G38),0) -> 0 | N38: Net Profit Ratio (In % )
D39: Revenue from Operations | E39: 0
B42: 10 | C42: Return On Capital Employed (In % ) | D42: Earnings Before Interst & Taxes | E42: 0 | F42: =+IFERROR(E42/E43,0) -> 0 | G42: 0 | H42: =+IFERROR(((F42-G42)/G42),0) -> 0 | N42: Return On Capital Employed (In % )
D43: Capital Employed | E43: 0
B46: 11 | C46: Return On Investment (In % ) | D46: Return/ Profit/ Earnings | E46: 0 | F46: =+IF(ISNUMBER(E46/E47),E46/E47,"N.A.") -> N.A. | G46: 0 | H46: =+IFERROR(((F46-G46)/G46),0) -> 0 | N46: Return On Investment (In % )
D47: Average Investment Fund | E47: 0
N49: =PROPER(C49)

Sheet Sheet2
A2: For Chart Flow
A3: K:\SOFTWARE\AUDIT\FINANCIAL
A7: NCE
A8: K:\SOFTWARE\AUDIT\AUDIT REPORT\FORMAT AR_NCE & LLP

Sheet FA - IT Act
A1: =BS!B2 -> [NAME OF THE COMPANY]
H3: =+BS!E5 -> (Amount in Rs. `000)
A4: Category of Assets | B4: Rate of Depreciation | C4: Opening WDV | D4: Additions/ (deductions) | F4: Total | G4: Depreciation | H4: Closing WDV
D5: Used for 180 days or more | E5: Less than 180 days
A6: Factory Building | B6: 0.4 | C6: 0 | D6: 0 | E6: 0 | F6: =+C6+D6+E6 -> 0 | G6: =ROUND(((C6+D6)*B6)+(E6*B6/2),1) -> 0 | H6: =F6-G6 -> 0
A7: Computers | B7: 0.4 | C7: 0 | D7: 0 | E7: 0 | F7: =+C7+D7+E7 -> 0 | G7: =ROUND(((C7+D7)*B7)+(E7*B7/2),1) -> 0 | H7: =F7-G7 -> 0
A8: Plant & machinery | B8: 0.15 | C8: 0 | D8: 0 | E8: 0 | F8: =+C8+D8+E8 -> 0 | G8: =ROUND(((C8+D8)*B8)+(E8*B8/2),1) -> 0 | H8: =F8-G8 -> 0
A9: Office equipment | B9: 0.15 | C9: 0 | D9: 0 | E9: 0 | F9: =+C9+D9+E9 -> 0 | G9: =ROUND(((C9+D9)*B9)+(E9*B9/2),1) -> 0 | H9: =F9-G9 -> 0
A10: Furniture and fixtures | B10: 0.1 | C10: 0 | D10: 0 | E10: 0 | F10: =+C10+D10+E10 -> 0 | G10: =ROUND(((C10+D10)*B10)+(E10*B10/2),1) -> 0 | H10: =F10-G10 -> 0
A11: Vehicles | B11: 0.15 | C11: 0 | D11: 0 | E11: 0 | F11: =+C11+D11+E11 -> 0 | G11: =ROUND(((C11+D11)*B11)+(E11*B11/2),1) -> 0 | H11: =F11-G11 -> 0
A12: Softaware | B12: 0.25 | C12: 0 | D12: 0 | E12: 0 | F12: =+C12+D12+E12 -> 0 | G12: =ROUND(((C12+D12)*B12)+(E12*B12/2),1) -> 0 | H12: =F12-G12 -> 0
A14: Total | C14: =SUM(C6:C13) -> 0 | D14: =SUM(D6:D13) -> 0 | E14: =SUM(E6:E13) -> 0 | F14: =SUM(F6:F13) -> 0 | G14: =SUM(G6:G13) -> 0 | H14: =SUM(H6:H13) -> 0

Sheet DT
A1: =BS!B2 -> [NAME OF THE COMPANY]
A4: Computation of Deferred Tax for the year ended 31st March, 2026
A5: Particulars | E5: =+BS!E5 -> (Amount in Rs. `000)
A7: Computation of Deferred Tax Assets / (Liability)
A9: WDV as on 31st March 2024 - as per Companies Act, 2013 | E9: =FA!L22 -> 0
A10: WDV as on 31st March 2024 - as per Income Tax Act, 1961 | E10: ='FA - IT Act'!H14 -> 0
E11: =E10-E9 -> 0
A12: Preliminary Expenses balances | E12: 0
A14: Timing Difference | E14: =SUM(E11:E13) -> 0
A15: Tax on above at applicable Tax rate 25.168% | E15: =E14*22%*1.1*1.04 -> 0
A16: Deferred Tax Assets to be shown in Balance Sheet | E16: =E15 -> 0
A18: Opening Deferred Tax | E18: =BS!F19 -> 0
A19: Deferred Tax to be transferred to Profit and Loss Account | E19: =E16-E18 -> 0

Sheet Sheet1

Sheet 03_Independent_Auditors_Report
A1: INDEPENDENT AUDITOR'S REPORT
A2: Illustrative statutory audit report for a company
B4: [Illustrative editable format – tailor wording to entity-specific facts, reporting framework, materiality, modifications and legal applicability before issue.]
B6: Opinion
B7: We have audited the accompanying financial statements of KWIKTEAM SUPPORT SERVICES PRIVATE LIMITED ("the Company"), which comprise the Balance Sheet as at 31 March, 2026, the Statement of Profit and Loss, the Cash Flow Statement for the year then ended, and notes to the financial statements, including a summary of material accounting policies and other explanatory information. In our opinion and to the best of our information and according to the explanations given to us, the aforesaid financial statements give the information required by the Companies Act, 2013 ("the Act") in the manner so required and give a true and fair view in conformity with the accounting principles generally accepted in India, of the state of affairs of the Company as at 31 March, 2026, and of its [profit/loss] and its cash flows for the year ended on that date.
B9: Basis for Opinion
B10: We conducted our audit in accordance with the Standards on Auditing specified under section 143(10) of the Act. Our responsibilities under those Standards are further described in the section titled 'Auditor's Responsibilities for the Audit of the Financial Statements' below. We are independent of the Company in accordance with the Code of Ethics issued by the Institute of Chartered Accountants of India together with the ethical requirements that are relevant to our audit of the financial statements, and we have fulfilled our other ethical responsibilities in accordance with these requirements and the Code of Ethics. We believe that the audit evidence we have obtained is sufficient and appropriate to provide a basis for our opinion.
B12: Key Audit Matters
B13: [Insert Key Audit Matter(s), if applicable, in the format: 'Why the matter was considered to be one of most significance in the audit' and 'How the matter was addressed in the audit'. If no key audit matters are required to be communicated, replace this block with an appropriate statement.]
B15: Information Other than the Financial Statements and Auditor's Report Thereon
B16: The Company's Board of Directors is responsible for the other information. The other information comprises the information included in the Board's Report and its annexures, but does not include the financial statements and our auditor's report thereon. Our opinion on the financial statements does not cover the other information and we do not express any form of assurance conclusion thereon. In connection with our audit, our responsibility is to read the other information when it becomes available and, in doing so, consider whether the other information is materially inconsistent with the financial statements or our knowledge obtained during the audit or otherwise appears to be materially misstated.
B18: Responsibilities of Management and Those Charged with Governance for the Financial Statements
B19: The Company's Board of Directors is responsible for the matters stated in section 134(5) of the Act with respect to the preparation of these financial statements that give a true and fair view of the financial position, financial performance and cash flows of the Company in accordance with the accounting principles generally accepted in India, including the Accounting Standards specified under section 133 of the Act, read with the Companies (Accounts) Rules, 2014. This responsibility also includes maintenance of adequate accounting records, safeguarding of assets, prevention and detection of frauds and other irregularities, selection and application of appropriate accounting policies, making reasonable and prudent estimates, and designing, implementing and maintaining adequate internal financial controls.
B21: Auditor's Responsibilities for the Audit of the Financial Statements
... B29: Insert modified opinion, emphasis of matter, other matter, material uncertainty related to going concern, KAM details and annexure references where required.

Sheet 04_Annexure_A_CARO_2020
A1: Annexure A to the Independent Auditor's Report
A2: Illustrative CARO 2020 clause-wise reporting matrix | H2: 31
A4: Clause | B4: Para | C4: Topic | D4: Illustrative reporting block (editable) | E4: WP / Ref.
A5: 1 | B5: 3(i) | C5: Property, Plant and Equipment / Intangible Assets | D5: [Insert clause-wise reporting on records, physical verification, title deeds, revaluation and benami proceedings.] | E5: [Ref]
A6: 2 | B6: 3(ii) | C6: Inventory and working capital limits | D6: [Insert reporting on physical verification of inventory, discrepancies and quarterly returns/statements filed with banks or financial institutions, if applicable.] | E6: [Ref]
A7: 3 | B7: 3(iii) | C7: Investments, guarantees, securities, loans and advances | D7: [Insert reporting on terms, schedule of repayment, overdue amounts, renewals/evergreening and loans repayable on demand, as applicable.] | E7: [Ref]
A8: 4 | B8: 3(iv) | C8: Compliance with sections 185 and 186 | D8: [Insert conclusion on loans, investments, guarantees and security covered under the Act.] | E8: [Ref]
A9: 5 | B9: 3(v) | C9: Deposits / deemed deposits | D9: [Insert reporting on acceptance of deposits or amounts deemed to be deposits and compliance with directives and sections 73 to 76.] | E9: [Ref]
A10: 6 | B10: 3(vi) | C10: Cost records | D10: [Insert whether maintenance of cost records has been specified and whether such accounts and records have been made and maintained.] | E10: [Ref]
A11: 7 | B11: 3(vii) | C11: Statutory dues | D11: [Insert reporting on regularity of undisputed statutory dues and disputed dues.] | E11: [Ref]
A12: 8 | B12: 3(viii) | C12: Previously unrecorded income surrendered in tax assessments | D12: [Insert whether any transactions not recorded in books have been surrendered or disclosed as income in tax assessments and treatment thereof.] | E12: [Ref]
A13: 9 | B13: 3(ix) | C13: Borrowings and utilisation of funds | D13: [Insert reporting on defaults in repayment, wilful defaulter status, application of term loans, utilisation of short-term funds and funds raised for subsidiaries/associates/JVs.] | E13: [Ref]
A14: 10 | B14: 3(x) | C14: Funds raised through IPO / FPO / debt instruments / private placement | D14: [Insert reporting on utilisation of funds and compliance with sections 42 and 62.] | E14: [Ref]
A15: 11 | B15: 3(xi) | C15: Fraud and whistle-blower complaints | D15: [Insert reporting on fraud by/on the company, section 143(12) filings and whistle-blower complaints considered.] | E15: [Ref]
A16: 12 | B16: 3(xii) | C16: Nidhi company requirements | D16: [Insert only if applicable; otherwise state not applicable.] | E16: [Ref]
... A24: 20 | B24: 3(xx) | C24: CSR obligations | D24: [Insert reporting on unspent CSR amounts and transfers, where applicable.] | E24: [Ref]
A26: Edit clause applicability and wording based on company size, exemptions, CARO applicability and audit conclusions. Replace non-applicable rows with explicit 'Not applicable' conclusions where appropriate.

Sheet 05_Annexure_B_IFC
A1: Annexure B to the Independent Auditor's Report
A2: Illustrative report on internal financial controls with reference to financial statements
B4: [Illustrative editable format – tailor wording to entity-specific facts, reporting framework, materiality, modifications and legal applicability before issue.]
B6: Report on the Internal Financial Controls with reference to Financial Statements
B7: We have audited the internal financial controls with reference to financial statements of KWIKTEAM SUPPORT SERVICES PRIVATE LIMITED as of 31 March, 2026 in conjunction with our audit of the financial statements of the Company for the year ended on that date.
B9: Management's Responsibility for Internal Financial Controls
B10: The Company's management is responsible for establishing and maintaining internal financial controls based on the criteria established by the Company considering the essential components of internal control stated in the Guidance Note on Audit of Internal Financial Controls Over Financial Reporting issued by the Institute of Chartered Accountants of India. These responsibilities include the design, implementation and maintenance of adequate internal financial controls that were operating effectively for ensuring the orderly and efficient conduct of business, including adherence to company policies, safeguarding of assets, prevention and detection of frauds and errors, accuracy and completeness of accounting records, and timely preparation of reliable financial information.
B12: Auditor's Responsibility
B13: Our responsibility is to express an opinion on the Company's internal financial controls with reference to financial statements based on our audit. We conducted our audit in accordance with the Guidance Note on Audit of Internal Financial Controls Over Financial Reporting and the Standards on Auditing, to the extent applicable. Those standards and the Guidance Note require that we plan and perform the audit to obtain reasonable assurance about whether adequate internal financial controls were established and maintained and whether such controls operated effectively in all material respects.
B15: Meaning of Internal Financial Controls with reference to Financial Statements
B16: A company's internal financial controls with reference to financial statements is a process designed to provide reasonable assurance regarding the reliability of financial reporting and the preparation of financial statements for external purposes in accordance with generally accepted accounting principles. Such controls include policies and procedures that (1) pertain to the maintenance of records that accurately and fairly reflect transactions; (2) provide reasonable assurance that transactions are recorded as necessary to permit preparation of financial statements; and (3) provide reasonable assurance regarding prevention or timely detection of unauthorised acquisition, use or disposition of assets.
B18: Inherent Limitations of Internal Financial Controls
B19: Because of the inherent limitations of internal financial controls with reference to financial statements, including the possibility of collusion or management override of controls, material misstatements due to error or fraud may occur and not be detected. Also, projections of any evaluation to future periods are subject to the risk that the controls may become inadequate because of changes in conditions or that the degree of compliance with the policies or procedures may deteriorate.
B21: Opinion
... B26: Modify or qualify this annexure where a material weakness or reporting exception exists.

Sheet 06_Form_3CA
A1: FORM NO. 3CA
A2: Audit report under section 44AB in a case where accounts have been audited under any other law
B4: [Illustrative format aligned to the current official form text. Tailor the wording and annexures before final issue.]
B6: 1. I / We report that the statutory audit of M/s. KWIKTEAM SUPPORT SERVICES PRIVATE LIMITED, SURAT, GUJARAT, PAN: AABCK1234Z was conducted by V J DESAI & CO. LLP in pursuance of the provisions of the Companies Act, 2013, and I / We annex hereto a copy of the audit report dated 16/05/2026 along with a copy of each of the audited Statement of Profit and Loss / Income and Expenditure Account, the audited Balance Sheet and documents declared by the said Act to be part of, or annexed to, such accounts.
B8: 2. The statement of particulars required to be furnished under section 44AB is annexed herewith in Form No. 3CD.
B10: 3. In my / our opinion and to the best of my / our information and according to examination of books of account including other relevant documents and explanations given to me / us, the particulars given in the said Form No. 3CD are true and correct subject to the following observations / qualifications, if any: (a) [ ] (b) [ ] (c) [ ].
B12: Signature and stamp / seal of the signatory Place: SURAT Name of the signatory: VIJAY J DESAI Date: 16/05/2026 Full address: SURAT, GUJARAT Membership No. / Certificate of Practice / Authority:
B14: Notes: Delete whichever is not applicable. Where any requirement is answered in the negative or with qualification, give reasons. The signatory should indicate the reference under which he / she is entitled to sign the report.

Sheet 07_Form_3CD_Part_A
A1: FORM NO. 3CD – PART A
A2: Statement of particulars required to be furnished under section 44AB of the Income-tax Act, 1961
A4: Clause | B4: Particulars | C4: Editable Response | D4: Ref.
A5: 1 | B5: Name of the assessee | C5: [Edit response]
A6: 2 | B6: Address | C6: [Edit response]
A7: 3 | B7: Permanent Account Number or Aadhaar Number | C7: [Edit response]
A8: 4 | B8: Whether liable to pay indirect tax (including GST); if yes, furnish registration number / GST number / other ID | C8: [Edit response]
A9: 5 | B9: Status | C9: [Edit response]
A10: 6 | B10: Previous year (from / to) | C10: [Edit response]
A11: 7 | B11: Assessment year | C11: [Edit response]
A12: 8 | B12: Relevant clause of section 44AB under which audit conducted | C12: [Edit response]
A13: 8A | B13: Whether opted for taxation under section 115BA / 115BAA / 115BAB / 115BAC / 115BAD / 115BAE | C13: [Edit response]
A15: Use the annexure and control sheets to maintain consistency across the tax audit report, financial statements and clause-wise disclosures.

Sheet 08_Form_3CD_09_to_20
A1: FORM NO. 3CD – PART B (Clauses 9 to 20)
A2: Editable clause-wise response matrix
A4: Clause | B4: Particulars / requirement | C4: Editable response / conclusion | D4: Annexure Ref.
A5: 9(a) | B5: If firm or association of persons, names of partners / members and their profit-sharing ratios | C5: [Insert response / conclusion / N.A. / see annexure] | D5: 3CD_Annx_Partners_9
A6: 9(b) | B6: Changes in partners / members or profit-sharing ratio since last date of preceding year | C6: [Insert response / conclusion / N.A. / see annexure] | D6: 3CD_Annx_Partners_9
A7: 10(a) | B7: Nature of business or profession carried on during the previous year | C7: [Insert response / conclusion / N.A. / see annexure]
A8: 10(b) | B8: Changes in the nature of business or profession | C8: [Insert response / conclusion / N.A. / see annexure]
A9: 11(a) | B9: Whether books of account are prescribed under section 44AA; if yes, list of books | C9: [Insert response / conclusion / N.A. / see annexure]
A10: 11(b) | B10: List of books of account maintained and addresses where kept, including system-generated books | C10: [Insert response / conclusion / N.A. / see annexure]
A11: 11(c) | B11: List of books of account and nature of relevant documents examined | C11: [Insert response / conclusion / N.A. / see annexure]
A12: 12 | B12: Whether profit and loss account includes profits assessable on presumptive basis; if yes, amount and relevant sections (including 44AD, 44ADA, 44AE, 44BBC etc.) | C12: [Insert response / conclusion / N.A. / see annexure]
A13: 13(a) | B13: Method of accounting employed | C13: [Insert response / conclusion / N.A. / see annexure]
A14: 13(b) | B14: Whether there was any change in method of accounting vis-a-vis immediately preceding year | C14: [Insert response / conclusion / N.A. / see annexure]
A15: 13(c) | B15: If yes, details of change and effect on profit or loss | C15: [Insert response / conclusion / N.A. / see annexure]
A16: 13(d) | B16: Whether any adjustment is required for compliance with ICDS notified under section 145(2) | C16: [Insert response / conclusion / N.A. / see annexure]
A17: 13(e) | B17: If yes, give details of such adjustments | C17: [Insert response / conclusion / N.A. / see annexure]
A18: 13(f) | B18: Disclosure as per ICDS (I, II, III, IV, V, VII, IX and X) | C18: [Insert response / conclusion / N.A. / see annexure]
... A23: 17 | B23: Land or building transferred for consideration less than stamp duty value / assessable value | C23: [Insert response / conclusion / N.A. / see annexure]
A24: 18 | B24: Particulars of depreciation allowable under the Income-tax Act, 1961 | C24: [Insert response / conclusion / N.A. / see annexure] | D24: 3CD_Annx_Depn_18
A25: 19 | B25: Amounts admissible under specific sections | C25: [Insert response / conclusion / N.A. / see annexure] | D25: 3CD_Annx_Deduction_19_33
A26: 20(a) | B26: Bonus or commission paid to employees where otherwise payable as profits or dividend | C26: [Insert response / conclusion / N.A. / see annexure]
A27: 20(b) | B27: Employees' contributions to funds referred to in section 36(1)(va) | C27: [Insert response / conclusion / N.A. / see annexure] | D27: 3CD_Annx_Disallow_21_26
A29: Tip: Use explicit 'Not applicable' conclusions for omitted / inapplicable clauses, and cross-reference supporting annexures or working papers in the final column.

Sheet 09_Form_3CD_21_to_30C
A1: FORM NO. 3CD – PART B (Clauses 21 to 30C)
A2: Editable clause-wise response matrix
A4: Clause | B4: Particulars / requirement | C4: Editable response / conclusion | D4: Annexure Ref.
A5: 21(a) | B5: Amounts debited to P&L account in the nature of capital, personal, political advertisement, club expenses, penalties / fines, compounding fees, prohibited benefits / perquisites and settlement expenditure | C5: [Insert response / conclusion / N.A. / see annexure] | D5: 3CD_Annx_Disallow_21_26
A6: 21(b) | B6: Amounts inadmissible under section 40(a) | C6: [Insert response / conclusion / N.A. / see annexure] | D6: 3CD_Annx_Disallow_21_26
A7: 21(c) | B7: Amounts inadmissible under section 40(b) / 40(ba) | C7: [Insert response / conclusion / N.A. / see annexure] | D7: 3CD_Annx_Disallow_21_26
A8: 21(d) | B8: Disallowance / deemed income under section 40A(3) / 40A(3A) | C8: [Insert response / conclusion / N.A. / see annexure] | D8: 3CD_Annx_Disallow_21_26
A9: 21(e) | B9: Provision for gratuity not allowable under section 40A(7) | C9: [Insert response / conclusion / N.A. / see annexure] | D9: 3CD_Annx_Disallow_21_26
A10: 21(f) | B10: Employer contribution not allowable under section 40A(9) | C10: [Insert response / conclusion / N.A. / see annexure] | D10: 3CD_Annx_Disallow_21_26
A11: 21(g) | B11: Particulars of contingent liabilities | C11: [Insert response / conclusion / N.A. / see annexure]
A12: 21(h) | B12: Deduction inadmissible under section 14A | C12: [Insert response / conclusion / N.A. / see annexure]
A13: 21(i) | B13: Amount inadmissible under proviso to section 36(1)(iii) | C13: [Insert response / conclusion / N.A. / see annexure]
A14: 22 | B14: MSMED Act interest inadmissible / amount payable to micro or small enterprise and overdue amount | C14: [Insert response / conclusion / N.A. / see annexure] | D14: 3CD_Annx_MSME_22_23
A15: 23 | B15: Payments made to persons specified under section 40A(2)(b) | C15: [Insert response / conclusion / N.A. / see annexure] | D15: 3CD_Annx_MSME_22_23
A16: 24 | B16: Amounts deemed to be profits and gains under section 32AD / 33AB / 33ABA / 33AC | C16: [Insert response / conclusion / N.A. / see annexure]
A17: 25 | B17: Any amount of profit chargeable under section 41 and computation thereof | C17: [Insert response / conclusion / N.A. / see annexure]
A18: 26 | B18: Amounts referred to in section 43B | C18: [Insert response / conclusion / N.A. / see annexure] | D18: 3CD_Annx_43B_26
A19: 27(a) | B19: CENVAT credits availed / utilised and treatment in accounts | C19: [Insert response / conclusion / N.A. / see annexure]
A20: 27(b) | B20: Prior period income or expenditure credited or debited to the profit and loss account | C20: [Insert response / conclusion / N.A. / see annexure]
A21: 29A | B21: Any amount includible under section 56(2)(ix) | C21: [Insert response / conclusion / N.A. / see annexure]
A22: 29B | B22: Any amount includible under section 56(2)(x) | C22: [Insert response / conclusion / N.A. / see annexure]
A23: 30 | B23: Amount borrowed on hundi repaid otherwise than through account payee cheque | C23: [Insert response / conclusion / N.A. / see annexure]
A24: 30A | B24: Primary adjustment to transfer price under section 92CE | C24: [Insert response / conclusion / N.A. / see annexure]
A25: 30B | B25: Interest expenditure under section 94B | C25: [Insert response / conclusion / N.A. / see annexure]
A26: 30C | B26: Impermissible avoidance arrangement under section 96 | C26: [Insert response / conclusion / N.A. / see annexure]
A28: Tip: Use explicit 'Not applicable' conclusions for omitted / inapplicable clauses, and cross-reference supporting annexures or working papers in the final column.

Sheet 10_Form_3CD_31_to_44
A1: FORM NO. 3CD – PART B (Clauses 31 to 44)
A2: Editable clause-wise response matrix
A4: Clause | B4: Particulars / requirement | C4: Editable response / conclusion | D4: Annexure Ref.
A5: 31(a) | B5: Loans or deposits exceeding limit under section 269SS taken or accepted during the previous year | C5: [Insert response / conclusion / N.A. / see annexure] | D5: 3CD_Annx_Loans_31
A6: 31(b) | B6: Specified sums exceeding limit under section 269SS taken or accepted | C6: [Insert response / conclusion / N.A. / see annexure] | D6: 3CD_Annx_Loans_31
A7: 31(ba) | B7: Receipts exceeding limit under section 269ST otherwise than by account payee instrument / ECS | C7: [Insert response / conclusion / N.A. / see annexure] | D7: 3CD_Annx_Loans_31
A8: 31(bb) | B8: Receipts exceeding limit under section 269ST by non-account payee cheque / draft | C8: [Insert response / conclusion / N.A. / see annexure] | D8: 3CD_Annx_Loans_31
A9: 31(bc) | B9: Payments exceeding limit under section 269ST otherwise than by account payee instrument / ECS | C9: [Insert response / conclusion / N.A. / see annexure] | D9: 3CD_Annx_Loans_31
A10: 31(bd) | B10: Payments exceeding limit under section 269ST by non-account payee cheque / draft | C10: [Insert response / conclusion / N.A. / see annexure] | D10: 3CD_Annx_Loans_31
A11: 31(c) | B11: Repayment of loan / deposit / specified advance exceeding limit under section 269T | C11: [Insert response / conclusion / N.A. / see annexure] | D11: 3CD_Annx_Loans_31
A12: 31(d) | B12: Repayment of loan / deposit / specified advance exceeding limit under section 269T received otherwise than by banking mode | C12: [Insert response / conclusion / N.A. / see annexure] | D12: 3CD_Annx_Loans_31
A13: 31(e) | B13: Repayment of loan / deposit / specified advance by non-account payee cheque / draft | C13: [Insert response / conclusion / N.A. / see annexure] | D13: 3CD_Annx_Loans_31
A14: 32(a) | B14: Brought forward losses / depreciation allowance details | C14: [Insert response / conclusion / N.A. / see annexure] | D14: 3CD_Annx_BF_Loss_32
A15: 32(b) | B15: Change in shareholding affecting carry forward under section 79 | C15: [Insert response / conclusion / N.A. / see annexure] | D15: 3CD_Annx_BF_Loss_32
... A24: 35(b) | B24: Quantitative details of principal raw materials / finished goods / by-products | C24: [Insert response / conclusion / N.A. / see annexure] | D24: 3CD_Annx_Quant_35
A25: 36A | B25: Dividend under section 2(22)(e) | C25: [Insert response / conclusion / N.A. / see annexure]
A26: 36B | B26: Buyback of shares under section 2(22)(f) | C26: [Insert response / conclusion / N.A. / see annexure]
A27: 37 | B27: Cost audit carried out; disqualification or disagreement reported by cost auditor | C27: [Insert response / conclusion / N.A. / see annexure]
A28: 38 | B28: Audit under Central Excise Act, 1944; disqualification or disagreement reported | C28: [Insert response / conclusion / N.A. / see annexure]
A29: 39 | B29: Audit under section 72A of the Finance Act, 1994; disqualification or disagreement reported | C29: [Insert response / conclusion / N.A. / see annexure]
A30: 40 | B30: Details regarding turnover, gross profit, etc. for previous and preceding previous year | C30: [Insert response / conclusion / N.A. / see annexure] | D30: 3CD_Annx_GP_40
A31: 41 | B31: Demand raised or refund issued under other tax laws during the previous year | C31: [Insert response / conclusion / N.A. / see annexure]
A32: 42 | B32: Requirement to furnish Form 61 / 61A / 61B and compliance status | C32: [Insert response / conclusion / N.A. / see annexure]
A33: 43 | B33: Requirement to furnish report under section 286 and related details | C33: [Insert response / conclusion / N.A. / see annexure]
A34: 44 | B34: Break-up of total expenditure of entities registered or not registered under GST | C34: [Insert response / conclusion / N.A. / see annexure] | D34: 3CD_Annx_GST_44
A36: Tip: Use explicit 'Not applicable' conclusions for omitted / inapplicable clauses, and cross-reference supporting annexures or working papers in the final column.

Sheet 11_3CD_Annx_Partners_9
A1: 3CD Annexure – Clause 9
A2: Partners / members and profit-sharing ratios
A4: Name | B4: PAN / Aadhaar | C4: Opening ratio | D4: Closing ratio | E4: Change date | F4: Remarks
A14: Use for firms / AOPs / LLPs where applicable.

Sheet 12_3CD_Annx_Depn_18
A1: 3CD Annexure – Clause 18
A2: Depreciation schedule as per Income-tax Act, 1961
A4: Block of asset | B4: Rate % | C4: Opening WDV | D4: Adjustment to WDV | E4: Additions <=180 days | F4: Additions >180 days | G4: Deductions | H4: Depreciation | I4: Closing WDV
A17: Total | C17: =SUM(C5:C16) -> 0 | D17: =SUM(D5:D16) -> 0 | E17: =SUM(E5:E16) -> 0 | F17: =SUM(F5:F16) -> 0 | G17: =SUM(G5:G16) -> 0 | H17: =SUM(H5:H16) -> 0 | I17: =SUM(I5:I16) -> 0
A19: This annexure can be reconciled with the fixed asset schedule / tax depreciation working.

Sheet 13_3CD_Annx_Disallow_21_26
A1: 3CD Annexure – Clauses 20 / 21 / 26
A2: Disallowances, employee contributions and section 43B support
A4: Date | B4: Nature / section | C4: Party / fund | D4: Description | E4: Amount as per books | F4: Amount allowable | G4: Amount disallowable | H4: Remarks
D17: Total | E17: =SUM(E5:E16) -> 0 | F17: =SUM(F5:F16) -> 0 | G17: =SUM(G5:G16) -> 0
A19: Use this annexure for employee contribution delays, 40(a), 40A(3), 43B and related disallowance support.

Sheet 14_3CD_Annx_MSME_22_23
A1: 3CD Annexure – Clauses 22 & 23
A2: MSMED Act dues and specified person payments
A4: Party | B4: MSME status / relationship | C4: Invoice / contract date | D4: Amount payable | E4: Paid within time | F4: Overdue amount | G4: Interest inadmissible | H4: Remarks
C15: Total | D15: =SUM(D5:D14) -> 0 | F15: =SUM(F5:F14) -> 0 | G15: =SUM(G5:G14) -> 0
A17: Separate micro and small enterprises from other related parties and maintain linkage to supporting confirmations.

Sheet 15_3CD_Annx_43B_26
A1: 3CD Annexure – Clause 26
A2: Amounts referred to in section 43B
A4: Nature of liability | B4: Opening unpaid | C4: Paid during year | D4: Closing unpaid | E4: Paid before return due date | F4: Allowable in current year | G4: Disallowable | H4: Remarks
A15: Total | B15: =SUM(B5:B14) -> 0 | C15: =SUM(C5:C14) -> 0 | D15: =SUM(D5:D14) -> 0 | E15: =SUM(E5:E14) -> 0 | F15: =SUM(F5:F14) -> 0 | G15: =SUM(G5:G14) -> 0
A17: State whether indirect taxes / cess / levy are routed through profit and loss account.

Sheet 16_3CD_Annx_Loans_31
A1: 3CD Annexure – Clause 31
A2: Loans / deposits / specified sums / 269SS / 269ST / 269T compliance matrix
