Workbook

Sheet Instructions
A1: TDS Data Entry — Client Template
A3: Challan Master sheet + four quarter entry tabs, cross-linked by dropdown — mirrors the software’s own Data Entry screen, where a challan is created once and every deductee entry picks it from a list.
A5: How This Template Works
A6: • This workbook has SIX sheets: this Instructions sheet, "Challan Master", and four entry tabs — Q1 Data, Q2 Data, Q3 Data, Q4 Data. Fill in Challan Master FIRST, then go to whichever quarter tab a deductee was actually paid in and record the entry there.
A7: • Challan Master: one row per PHYSICAL challan, entered exactly ONCE, no matter how many quarters or deductees draw against it. Fill BSR Code, Challan Serial No., Date of Deposit, Minor Head, Tax Deposited (all four marked * are mandatory — leaving one blank highlights that cell pink and the Row 2 banner counts it as a failure), plus Surcharge/Cess/Interest/Others/Late Fees if applicable.
A8: • Quarter tabs (Q1–Q4 Data): every row is ONE deductee entry. The first editable field, "Challan (select)", is a dropdown listing every challan already on Challan Master — pick the right one and its BSR Code, Serial No., Date of Deposit, Minor Head, Tax Deposited and Section are pulled from Challan Master automatically wherever a formula needs them (interest calc, section-rate lookup). There is no more separate "Challan row" to type on a quarter tab, and no way to mistype or leave blank the BSR/Serial link — you are always picking a challan that already exists.
A9: • The entry’s own "Section*" (for TDS rate lookup) stays independently editable — pick the section that actually applies to THIS payment, regardless of whichever Section is registered on the linked challan (one challan can legitimately cover deductees under more than one section).
A10: • CHALLAN CARRY-FORWARD: Challan Master’s "Amount Used Q1/Q2/Q3/Q4" columns sum every entry linked to that challan on each specific quarter tab; "Total Amount Used", "Allocatable" and "Unconsumed / Balance" total across all four. Post part of a challan’s entries in Q1 and the rest in Q2 — the challan’s own row updates live either way, exactly like the software’s own database lookup.
A11: • "Status" on Challan Master (green, auto) shows Over-applied / Fully Utilised / Unconsumed for each challan; an Over-applied challan’s entire row is highlighted red on Challan Master, AND every entry on every quarter tab that references it is also highlighted red (via the "Challan Status (ref)" column) so you see the problem from wherever you’re looking, not just on Challan Master.
A12: • Row 2 on Challan Master is a live banner: over-applied challans + challans missing a mandatory field. Row 2 on each quarter tab is a separate live banner scoped to that tab: entries missing a Challan selection + entries posted against an already over-applied challan.
A13: • "Rate of TDS" calculates automatically from Section + Deductee Type (detected from the PAN’s 4th character, same P/H/C/F/L/T/A mapping the software uses); "TDS Amount" = Amount Paid × Rate; "Interest Amount" follows Section 201(1A) — 1.5% per month (or part) late, from the deduction month’s 7th-of-next-month due date to the linked challan’s own deposit date, now a simple same-row lookup instead of a cross-sheet search.
A14: • "PAN Not Available" calculates automatically — Y whenever PAN is blank or not in valid PAN format, N otherwise; a no-PAN row is highlighted pink and gets the flat higher no-PAN rate under Section 206AA, same as the software.
... A20: • Lower Deduction Rate now drives the TDS calculation directly: whenever it’s filled (including an explicit 0 for a NIL-rate certificate), "Rate of TDS" and "TDS Amount" use that figure instead of the section’s default rate. Leave it blank and the section rate applies exactly as before. Note: this is a template-only enhancement — the live software does not yet apply Lower Deduction Rate to its own TDS calculation, so the two will disagree on this one point for a Reason-A row until/unless the software is updated to match.

Sheet Rate Lookup
A1: 1004 : [192A] : 393(7) – Premature withdrawal from Employees' Provident Fund | B1: 10 | C1: 10 | D1: 20
A2: 192B — Salary | B2: 0 | C2: 0 | D2: 20
A3: 1019 : [193] : 393(1) [Table: S.N. 5(i)] – Interest on securities | B3: 10 | C3: 10 | D3: 20
A4: 1029 : [194] : 393(1) [Table: S.N. 7] – Dividend | B4: 10 | C4: 10 | D4: 20
A5: 1021 : [194A] : 393(1) [Table: S.N. 5(ii).D(b)] – Interest other than securities - Other Individuals | B5: 10 | C5: 10 | D5: 20
A6: 1022 : [194A- Other than Bank] : 393(1) [Table: S.N. 5(iii)] – Interest other than securities - Others | B6: 10 | C6: 10 | D6: 20
A7: 1020 : [194A-SC] : 393(1) [Table: S.N. 5(ii).D(a)] – Interest other than securities - Senior Citizens | B7: 10 | C7: 10 | D7: 20
A8: 1058 : [194B] : 393(3) [Table: Sl. No. 1] – Winnings from lottery, crossword puzzles, card games and other games | B8: 30 | C8: 30 | D8: 30
A9: 1062 : [194BB] : 393(3) [Table: S.No. 3] – Winnings from horse races | B9: 30 | C9: 30 | D9: 30
A10: 194C — Contractor / Sub-contractor | B10: 1 | C10: 2 | D10: 20
A11: 1023 : [194C(a)] : 393(1) [Table: S.N. 6(i).D(a)] – Payments to contractors and sub-contractors (Individual/HUF) | B11: 1 | C11: 1 | D11: 20
A12: 1024 : [194C(b)] : 393(1) [Table: S.N. 6(i).D(b)] – Payments to contractors and sub-contractors (Others) | B12: 2 | C12: 2 | D12: 20
... A37: 1067 : [194T] : 393(3) [Table: S.N. 7] – Payment to partners of a firm (salary/remuneration/interest) | B37: 10 | C37: 0 | D37: 20

Sheet Challan Master
A1: Challan Master — enter every challan ONCE here; quarter tabs pick it from a dropdown
A2: =IF(AND(COUNTIF($AA$4:$AA$207,"Over-applied")=0,SUMPRODUCT(($C$4:$C$207<>"")*((($D$4:$D$207="")+($E$4:$E$207="")+($G$4:$G$207=""))>0))=0),"✅ Validation Successful — no over-applied challans, no missing mandatory fields ("&COUNTIF($C$4:$C$207,"<>")&" challans on file).","❌ VALIDATION FAILED — "&COUNTIF($AA$4:$AA$207,"Over-applied")&" challan(s) Over-applied, "&SUMPRODUCT(($C$4:$C$207<>"")*((($D$4:$D$207="")+($E$4:$E$207="")+($G$4:$G$207=""))>0))&" challan(s) missing a mandatory field (Date of Deposit / Minor Head / Tax Deposited). See the red/pink-highlighted row(s) below.")
A3: Sr. No. | B3: BSR Code* | C3: Challan Serial No.* | D3: Date of Deposit* | E3: Minor Head* | F3: Section | G3: Tax Deposited (₹)* | H3: Surcharge Deposited (₹) | I3: Education Cess Deposited (₹) | J3: Interest Deposited (₹) | K3: Others Deposited (₹) | L3: Late Fees u/s 234E (₹) | M3: Total Challan Amount (₹) | N3: Bank Name | O3: Book Entry? | P3: Transfer Voucher No. | Q3: Cheque/DD No. | R3: Remarks | S3: Dropdown Label (internal) | T3: Amount Used Q1 (₹) | U3: Amount Used Q2 (₹) | V3: Amount Used Q3 (₹) | W3: Amount Used Q4 (₹) | X3: Total Amount Used (₹) | Y3: Allocatable (₹) | Z3: Unconsumed / Balance (₹) | AA3: Status
A4: =IF($C4="","",COUNTIF($C$4:$C4,"<>")) | M4: =IF($C4="","",G4+H4+I4+J4+K4+L4) | S4: =IF($C4="","",C4&" | BSR "&B4&" | "&TEXT(D4,"dd-mm-yyyy")&" | ₹"&TEXT(M4,"#,##0")) | T4: =IF($C4="","",SUMIFS('Q1 Data'!$K$4:$K$207,'Q1 Data'!$B$4:$B$207,$S4)+SUMIFS('Q1 Data'!$N$4:$N$207,'Q1 Data'!$B$4:$B$207,$S4)+SUMIFS('Q1 Data'!$L$4:$L$207,'Q1 Data'!$B$4:$B$207,$S4)) | U4: =IF($C4="","",SUMIFS('Q2 Data'!$K$4:$K$207,'Q2 Data'!$B$4:$B$207,$S4)+SUMIFS('Q2 Data'!$N$4:$N$207,'Q2 Data'!$B$4:$B$207,$S4)+SUMIFS('Q2 Data'!$L$4:$L$207,'Q2 Data'!$B$4:$B$207,$S4)) | V4: =IF($C4="","",SUMIFS('Q3 Data'!$K$4:$K$207,'Q3 Data'!$B$4:$B$207,$S4)+SUMIFS('Q3 Data'!$N$4:$N$207,'Q3 Data'!$B$4:$B$207,$S4)+SUMIFS('Q3 Data'!$L$4:$L$207,'Q3 Data'!$B$4:$B$207,$S4)) | W4: =IF($C4="","",SUMIFS('Q4 Data'!$K$4:$K$207,'Q4 Data'!$B$4:$B$207,$S4)+SUMIFS('Q4 Data'!$N$4:$N$207,'Q4 Data'!$B$4:$B$207,$S4)+SUMIFS('Q4 Data'!$L$4:$L$207,'Q4 Data'!$B$4:$B$207,$S4)) | X4: =IF($C4="","",T4+U4+V4+W4) | Y4: =IF($C4="","",M4-L4) | Z4: =IF($C4="","",Y4-X4) | AA4: =IF($C4="","",IF(ROUND(X4-Y4,2)>0,"Over-applied",IF(ROUND(X4-Y4,2)=0,"Fully Utilised","Unconsumed")))
A5: =IF($C5="","",COUNTIF($C$4:$C5,"<>")) | M5: =IF($C5="","",G5+H5+I5+J5+K5+L5) | S5: =IF($C5="","",C5&" | BSR "&B5&" | "&TEXT(D5,"dd-mm-yyyy")&" | ₹"&TEXT(M5,"#,##0")) | T5: =IF($C5="","",SUMIFS('Q1 Data'!$K$4:$K$207,'Q1 Data'!$B$4:$B$207,$S5)+SUMIFS('Q1 Data'!$N$4:$N$207,'Q1 Data'!$B$4:$B$207,$S5)+SUMIFS('Q1 Data'!$L$4:$L$207,'Q1 Data'!$B$4:$B$207,$S5)) | U5: =IF($C5="","",SUMIFS('Q2 Data'!$K$4:$K$207,'Q2 Data'!$B$4:$B$207,$S5)+SUMIFS('Q2 Data'!$N$4:$N$207,'Q2 Data'!$B$4:$B$207,$S5)+SUMIFS('Q2 Data'!$L$4:$L$207,'Q2 Data'!$B$4:$B$207,$S5)) | V5: =IF($C5="","",SUMIFS('Q3 Data'!$K$4:$K$207,'Q3 Data'!$B$4:$B$207,$S5)+SUMIFS('Q3 Data'!$N$4:$N$207,'Q3 Data'!$B$4:$B$207,$S5)+SUMIFS('Q3 Data'!$L$4:$L$207,'Q3 Data'!$B$4:$B$207,$S5)) | W5: =IF($C5="","",SUMIFS('Q4 Data'!$K$4:$K$207,'Q4 Data'!$B$4:$B$207,$S5)+SUMIFS('Q4 Data'!$N$4:$N$207,'Q4 Data'!$B$4:$B$207,$S5)+SUMIFS('Q4 Data'!$L$4:$L$207,'Q4 Data'!$B$4:$B$207,$S5)) | X5: =IF($C5="","",T5+U5+V5+W5) | Y5: =IF($C5="","",M5-L5) | Z5: =IF($C5="","",Y5-X5) | AA5: =IF($C5="","",IF(ROUND(X5-Y5,2)>0,"Over-applied",IF(ROUND(X5-Y5,2)=0,"Fully Utilised","Unconsumed")))
A6: =IF($C6="","",COUNTIF($C$4:$C6,"<>")) | M6: =IF($C6="","",G6+H6+I6+J6+K6+L6) | S6: =IF($C6="","",C6&" | BSR "&B6&" | "&TEXT(D6,"dd-mm-yyyy")&" | ₹"&TEXT(M6,"#,##0")) | T6: =IF($C6="","",SUMIFS('Q1 Data'!$K$4:$K$207,'Q1 Data'!$B$4:$B$207,$S6)+SUMIFS('Q1 Data'!$N$4:$N$207,'Q1 Data'!$B$4:$B$207,$S6)+SUMIFS('Q1 Data'!$L$4:$L$207,'Q1 Data'!$B$4:$B$207,$S6)) | U6: =IF($C6="","",SUMIFS('Q2 Data'!$K$4:$K$207,'Q2 Data'!$B$4:$B$207,$S6)+SUMIFS('Q2 Data'!$N$4:$N$207,'Q2 Data'!$B$4:$B$207,$S6)+SUMIFS('Q2 Data'!$L$4:$L$207,'Q2 Data'!$B$4:$B$207,$S6)) | V6: =IF($C6="","",SUMIFS('Q3 Data'!$K$4:$K$207,'Q3 Data'!$B$4:$B$207,$S6)+SUMIFS('Q3 Data'!$N$4:$N$207,'Q3 Data'!$B$4:$B$207,$S6)+SUMIFS('Q3 Data'!$L$4:$L$207,'Q3 Data'!$B$4:$B$207,$S6)) | W6: =IF($C6="","",SUMIFS('Q4 Data'!$K$4:$K$207,'Q4 Data'!$B$4:$B$207,$S6)+SUMIFS('Q4 Data'!$N$4:$N$207,'Q4 Data'!$B$4:$B$207,$S6)+SUMIFS('Q4 Data'!$L$4:$L$207,'Q4 Data'!$B$4:$B$207,$S6)) | X6: =IF($C6="","",T6+U6+V6+W6) | Y6: =IF($C6="","",M6-L6) | Z6: =IF($C6="","",Y6-X6) | AA6: =IF($C6="","",IF(ROUND(X6-Y6,2)>0,"Over-applied",IF(ROUND(X6-Y6,2)=0,"Fully Utilised","Unconsumed")))
A7: =IF($C7="","",COUNTIF($C$4:$C7,"<>")) | M7: =IF($C7="","",G7+H7+I7+J7+K7+L7) | S7: =IF($C7="","",C7&" | BSR "&B7&" | "&TEXT(D7,"dd-mm-yyyy")&" | ₹"&TEXT(M7,"#,##0")) | T7: =IF($C7="","",SUMIFS('Q1 Data'!$K$4:$K$207,'Q1 Data'!$B$4:$B$207,$S7)+SUMIFS('Q1 Data'!$N$4:$N$207,'Q1 Data'!$B$4:$B$207,$S7)+SUMIFS('Q1 Data'!$L$4:$L$207,'Q1 Data'!$B$4:$B$207,$S7)) | U7: =IF($C7="","",SUMIFS('Q2 Data'!$K$4:$K$207,'Q2 Data'!$B$4:$B$207,$S7)+SUMIFS('Q2 Data'!$N$4:$N$207,'Q2 Data'!$B$4:$B$207,$S7)+SUMIFS('Q2 Data'!$L$4:$L$207,'Q2 Data'!$B$4:$B$207,$S7)) | V7: =IF($C7="","",SUMIFS('Q3 Data'!$K$4:$K$207,'Q3 Data'!$B$4:$B$207,$S7)+SUMIFS('Q3 Data'!$N$4:$N$207,'Q3 Data'!$B$4:$B$207,$S7)+SUMIFS('Q3 Data'!$L$4:$L$207,'Q3 Data'!$B$4:$B$207,$S7)) | W7: =IF($C7="","",SUMIFS('Q4 Data'!$K$4:$K$207,'Q4 Data'!$B$4:$B$207,$S7)+SUMIFS('Q4 Data'!$N$4:$N$207,'Q4 Data'!$B$4:$B$207,$S7)+SUMIFS('Q4 Data'!$L$4:$L$207,'Q4 Data'!$B$4:$B$207,$S7)) | X7: =IF($C7="","",T7+U7+V7+W7) | Y7: =IF($C7="","",M7-L7) | Z7: =IF($C7="","",Y7-X7) | AA7: =IF($C7="","",IF(ROUND(X7-Y7,2)>0,"Over-applied",IF(ROUND(X7-Y7,2)=0,"Fully Utilised","Unconsumed")))
A8: =IF($C8="","",COUNTIF($C$4:$C8,"<>")) | M8: =IF($C8="","",G8+H8+I8+J8+K8+L8) | S8: =IF($C8="","",C8&" | BSR "&B8&" | "&TEXT(D8,"dd-mm-yyyy")&" | ₹"&TEXT(M8,"#,##0")) | T8: =IF($C8="","",SUMIFS('Q1 Data'!$K$4:$K$207,'Q1 Data'!$B$4:$B$207,$S8)+SUMIFS('Q1 Data'!$N$4:$N$207,'Q1 Data'!$B$4:$B$207,$S8)+SUMIFS('Q1 Data'!$L$4:$L$207,'Q1 Data'!$B$4:$B$207,$S8)) | U8: =IF($C8="","",SUMIFS('Q2 Data'!$K$4:$K$207,'Q2 Data'!$B$4:$B$207,$S8)+SUMIFS('Q2 Data'!$N$4:$N$207,'Q2 Data'!$B$4:$B$207,$S8)+SUMIFS('Q2 Data'!$L$4:$L$207,'Q2 Data'!$B$4:$B$207,$S8)) | V8: =IF($C8="","",SUMIFS('Q3 Data'!$K$4:$K$207,'Q3 Data'!$B$4:$B$207,$S8)+SUMIFS('Q3 Data'!$N$4:$N$207,'Q3 Data'!$B$4:$B$207,$S8)+SUMIFS('Q3 Data'!$L$4:$L$207,'Q3 Data'!$B$4:$B$207,$S8)) | W8: =IF($C8="","",SUMIFS('Q4 Data'!$K$4:$K$207,'Q4 Data'!$B$4:$B$207,$S8)+SUMIFS('Q4 Data'!$N$4:$N$207,'Q4 Data'!$B$4:$B$207,$S8)+SUMIFS('Q4 Data'!$L$4:$L$207,'Q4 Data'!$B$4:$B$207,$S8)) | X8: =IF($C8="","",T8+U8+V8+W8) | Y8: =IF($C8="","",M8-L8) | Z8: =IF($C8="","",Y8-X8) | AA8: =IF($C8="","",IF(ROUND(X8-Y8,2)>0,"Over-applied",IF(ROUND(X8-Y8,2)=0,"Fully Utilised","Unconsumed")))
A9: =IF($C9="","",COUNTIF($C$4:$C9,"<>")) | M9: =IF($C9="","",G9+H9+I9+J9+K9+L9) | S9: =IF($C9="","",C9&" | BSR "&B9&" | "&TEXT(D9,"dd-mm-yyyy")&" | ₹"&TEXT(M9,"#,##0")) | T9: =IF($C9="","",SUMIFS('Q1 Data'!$K$4:$K$207,'Q1 Data'!$B$4:$B$207,$S9)+SUMIFS('Q1 Data'!$N$4:$N$207,'Q1 Data'!$B$4:$B$207,$S9)+SUMIFS('Q1 Data'!$L$4:$L$207,'Q1 Data'!$B$4:$B$207,$S9)) | U9: =IF($C9="","",SUMIFS('Q2 Data'!$K$4:$K$207,'Q2 Data'!$B$4:$B$207,$S9)+SUMIFS('Q2 Data'!$N$4:$N$207,'Q2 Data'!$B$4:$B$207,$S9)+SUMIFS('Q2 Data'!$L$4:$L$207,'Q2 Data'!$B$4:$B$207,$S9)) | V9: =IF($C9="","",SUMIFS('Q3 Data'!$K$4:$K$207,'Q3 Data'!$B$4:$B$207,$S9)+SUMIFS('Q3 Data'!$N$4:$N$207,'Q3 Data'!$B$4:$B$207,$S9)+SUMIFS('Q3 Data'!$L$4:$L$207,'Q3 Data'!$B$4:$B$207,$S9)) | W9: =IF($C9="","",SUMIFS('Q4 Data'!$K$4:$K$207,'Q4 Data'!$B$4:$B$207,$S9)+SUMIFS('Q4 Data'!$N$4:$N$207,'Q4 Data'!$B$4:$B$207,$S9)+SUMIFS('Q4 Data'!$L$4:$L$207,'Q4 Data'!$B$4:$B$207,$S9)) | X9: =IF($C9="","",T9+U9+V9+W9) | Y9: =IF($C9="","",M9-L9) | Z9: =IF($C9="","",Y9-X9) | AA9: =IF($C9="","",IF(ROUND(X9-Y9,2)>0,"Over-applied",IF(ROUND(X9-Y9,2)=0,"Fully Utilised","Unconsumed")))
A10: =IF($C10="","",COUNTIF($C$4:$C10,"<>")) | M10: =IF($C10="","",G10+H10+I10+J10+K10+L10) | S10: =IF($C10="","",C10&" | BSR "&B10&" | "&TEXT(D10,"dd-mm-yyyy")&" | ₹"&TEXT(M10,"#,##0")) | T10: =IF($C10="","",SUMIFS('Q1 Data'!$K$4:$K$207,'Q1 Data'!$B$4:$B$207,$S10)+SUMIFS('Q1 Data'!$N$4:$N$207,'Q1 Data'!$B$4:$B$207,$S10)+SUMIFS('Q1 Data'!$L$4:$L$207,'Q1 Data'!$B$4:$B$207,$S10)) | U10: =IF($C10="","",SUMIFS('Q2 Data'!$K$4:$K$207,'Q2 Data'!$B$4:$B$207,$S10)+SUMIFS('Q2 Data'!$N$4:$N$207,'Q2 Data'!$B$4:$B$207,$S10)+SUMIFS('Q2 Data'!$L$4:$L$207,'Q2 Data'!$B$4:$B$207,$S10)) | V10: =IF($C10="","",SUMIFS('Q3 Data'!$K$4:$K$207,'Q3 Data'!$B$4:$B$207,$S10)+SUMIFS('Q3 Data'!$N$4:$N$207,'Q3 Data'!$B$4:$B$207,$S10)+SUMIFS('Q3 Data'!$L$4:$L$207,'Q3 Data'!$B$4:$B$207,$S10)) | W10: =IF($C10="","",SUMIFS('Q4 Data'!$K$4:$K$207,'Q4 Data'!$B$4:$B$207,$S10)+SUMIFS('Q4 Data'!$N$4:$N$207,'Q4 Data'!$B$4:$B$207,$S10)+SUMIFS('Q4 Data'!$L$4:$L$207,'Q4 Data'!$B$4:$B$207,$S10)) | X10: =IF($C10="","",T10+U10+V10+W10) | Y10: =IF($C10="","",M10-L10) | Z10: =IF($C10="","",Y10-X10) | AA10: =IF($C10="","",IF(ROUND(X10-Y10,2)>0,"Over-applied",IF(ROUND(X10-Y10,2)=0,"Fully Utilised","Unconsumed")))
A11: =IF($C11="","",COUNTIF($C$4:$C11,"<>")) | M11: =IF($C11="","",G11+H11+I11+J11+K11+L11) | S11: =IF($C11="","",C11&" | BSR "&B11&" | "&TEXT(D11,"dd-mm-yyyy")&" | ₹"&TEXT(M11,"#,##0")) | T11: =IF($C11="","",SUMIFS('Q1 Data'!$K$4:$K$207,'Q1 Data'!$B$4:$B$207,$S11)+SUMIFS('Q1 Data'!$N$4:$N$207,'Q1 Data'!$B$4:$B$207,$S11)+SUMIFS('Q1 Data'!$L$4:$L$207,'Q1 Data'!$B$4:$B$207,$S11)) | U11: =IF($C11="","",SUMIFS('Q2 Data'!$K$4:$K$207,'Q2 Data'!$B$4:$B$207,$S11)+SUMIFS('Q2 Data'!$N$4:$N$207,'Q2 Data'!$B$4:$B$207,$S11)+SUMIFS('Q2 Data'!$L$4:$L$207,'Q2 Data'!$B$4:$B$207,$S11)) | V11: =IF($C11="","",SUMIFS('Q3 Data'!$K$4:$K$207,'Q3 Data'!$B$4:$B$207,$S11)+SUMIFS('Q3 Data'!$N$4:$N$207,'Q3 Data'!$B$4:$B$207,$S11)+SUMIFS('Q3 Data'!$L$4:$L$207,'Q3 Data'!$B$4:$B$207,$S11)) | W11: =IF($C11="","",SUMIFS('Q4 Data'!$K$4:$K$207,'Q4 Data'!$B$4:$B$207,$S11)+SUMIFS('Q4 Data'!$N$4:$N$207,'Q4 Data'!$B$4:$B$207,$S11)+SUMIFS('Q4 Data'!$L$4:$L$207,'Q4 Data'!$B$4:$B$207,$S11)) | X11: =IF($C11="","",T11+U11+V11+W11) | Y11: =IF($C11="","",M11-L11) | Z11: =IF($C11="","",Y11-X11) | AA11: =IF($C11="","",IF(ROUND(X11-Y11,2)>0,"Over-applied",IF(ROUND(X11-Y11,2)=0,"Fully Utilised","Unconsumed")))
A12: =IF($C12="","",COUNTIF($C$4:$C12,"<>")) | M12: =IF($C12="","",G12+H12+I12+J12+K12+L12) | S12: =IF($C12="","",C12&" | BSR "&B12&" | "&TEXT(D12,"dd-mm-yyyy")&" | ₹"&TEXT(M12,"#,##0")) | T12: =IF($C12="","",SUMIFS('Q1 Data'!$K$4:$K$207,'Q1 Data'!$B$4:$B$207,$S12)+SUMIFS('Q1 Data'!$N$4:$N$207,'Q1 Data'!$B$4:$B$207,$S12)+SUMIFS('Q1 Data'!$L$4:$L$207,'Q1 Data'!$B$4:$B$207,$S12)) | U12: =IF($C12="","",SUMIFS('Q2 Data'!$K$4:$K$207,'Q2 Data'!$B$4:$B$207,$S12)+SUMIFS('Q2 Data'!$N$4:$N$207,'Q2 Data'!$B$4:$B$207,$S12)+SUMIFS('Q2 Data'!$L$4:$L$207,'Q2 Data'!$B$4:$B$207,$S12)) | V12: =IF($C12="","",SUMIFS('Q3 Data'!$K$4:$K$207,'Q3 Data'!$B$4:$B$207,$S12)+SUMIFS('Q3 Data'!$N$4:$N$207,'Q3 Data'!$B$4:$B$207,$S12)+SUMIFS('Q3 Data'!$L$4:$L$207,'Q3 Data'!$B$4:$B$207,$S12)) | W12: =IF($C12="","",SUMIFS('Q4 Data'!$K$4:$K$207,'Q4 Data'!$B$4:$B$207,$S12)+SUMIFS('Q4 Data'!$N$4:$N$207,'Q4 Data'!$B$4:$B$207,$S12)+SUMIFS('Q4 Data'!$L$4:$L$207,'Q4 Data'!$B$4:$B$207,$S12)) | X12: =IF($C12="","",T12+U12+V12+W12) | Y12: =IF($C12="","",M12-L12) | Z12: =IF($C12="","",Y12-X12) | AA12: =IF($C12="","",IF(ROUND(X12-Y12,2)>0,"Over-applied",IF(ROUND(X12-Y12,2)=0,"Fully Utilised","Unconsumed")))
A13: =IF($C13="","",COUNTIF($C$4:$C13,"<>")) | M13: =IF($C13="","",G13+H13+I13+J13+K13+L13) | S13: =IF($C13="","",C13&" | BSR "&B13&" | "&TEXT(D13,"dd-mm-yyyy")&" | ₹"&TEXT(M13,"#,##0")) | T13: =IF($C13="","",SUMIFS('Q1 Data'!$K$4:$K$207,'Q1 Data'!$B$4:$B$207,$S13)+SUMIFS('Q1 Data'!$N$4:$N$207,'Q1 Data'!$B$4:$B$207,$S13)+SUMIFS('Q1 Data'!$L$4:$L$207,'Q1 Data'!$B$4:$B$207,$S13)) | U13: =IF($C13="","",SUMIFS('Q2 Data'!$K$4:$K$207,'Q2 Data'!$B$4:$B$207,$S13)+SUMIFS('Q2 Data'!$N$4:$N$207,'Q2 Data'!$B$4:$B$207,$S13)+SUMIFS('Q2 Data'!$L$4:$L$207,'Q2 Data'!$B$4:$B$207,$S13)) | V13: =IF($C13="","",SUMIFS('Q3 Data'!$K$4:$K$207,'Q3 Data'!$B$4:$B$207,$S13)+SUMIFS('Q3 Data'!$N$4:$N$207,'Q3 Data'!$B$4:$B$207,$S13)+SUMIFS('Q3 Data'!$L$4:$L$207,'Q3 Data'!$B$4:$B$207,$S13)) | W13: =IF($C13="","",SUMIFS('Q4 Data'!$K$4:$K$207,'Q4 Data'!$B$4:$B$207,$S13)+SUMIFS('Q4 Data'!$N$4:$N$207,'Q4 Data'!$B$4:$B$207,$S13)+SUMIFS('Q4 Data'!$L$4:$L$207,'Q4 Data'!$B$4:$B$207,$S13)) | X13: =IF($C13="","",T13+U13+V13+W13) | Y13: =IF($C13="","",M13-L13) | Z13: =IF($C13="","",Y13-X13) | AA13: =IF($C13="","",IF(ROUND(X13-Y13,2)>0,"Over-applied",IF(ROUND(X13-Y13,2)=0,"Fully Utilised","Unconsumed")))
A14: =IF($C14="","",COUNTIF($C$4:$C14,"<>")) | M14: =IF($C14="","",G14+H14+I14+J14+K14+L14) | S14: =IF($C14="","",C14&" | BSR "&B14&" | "&TEXT(D14,"dd-mm-yyyy")&" | ₹"&TEXT(M14,"#,##0")) | T14: =IF($C14="","",SUMIFS('Q1 Data'!$K$4:$K$207,'Q1 Data'!$B$4:$B$207,$S14)+SUMIFS('Q1 Data'!$N$4:$N$207,'Q1 Data'!$B$4:$B$207,$S14)+SUMIFS('Q1 Data'!$L$4:$L$207,'Q1 Data'!$B$4:$B$207,$S14)) | U14: =IF($C14="","",SUMIFS('Q2 Data'!$K$4:$K$207,'Q2 Data'!$B$4:$B$207,$S14)+SUMIFS('Q2 Data'!$N$4:$N$207,'Q2 Data'!$B$4:$B$207,$S14)+SUMIFS('Q2 Data'!$L$4:$L$207,'Q2 Data'!$B$4:$B$207,$S14)) | V14: =IF($C14="","",SUMIFS('Q3 Data'!$K$4:$K$207,'Q3 Data'!$B$4:$B$207,$S14)+SUMIFS('Q3 Data'!$N$4:$N$207,'Q3 Data'!$B$4:$B$207,$S14)+SUMIFS('Q3 Data'!$L$4:$L$207,'Q3 Data'!$B$4:$B$207,$S14)) | W14: =IF($C14="","",SUMIFS('Q4 Data'!$K$4:$K$207,'Q4 Data'!$B$4:$B$207,$S14)+SUMIFS('Q4 Data'!$N$4:$N$207,'Q4 Data'!$B$4:$B$207,$S14)+SUMIFS('Q4 Data'!$L$4:$L$207,'Q4 Data'!$B$4:$B$207,$S14)) | X14: =IF($C14="","",T14+U14+V14+W14) | Y14: =IF($C14="","",M14-L14) | Z14: =IF($C14="","",Y14-X14) | AA14: =IF($C14="","",IF(ROUND(X14-Y14,2)>0,"Over-applied",IF(ROUND(X14-Y14,2)=0,"Fully Utilised","Unconsumed")))
A15: =IF($C15="","",COUNTIF($C$4:$C15,"<>")) | M15: =IF($C15="","",G15+H15+I15+J15+K15+L15) | S15: =IF($C15="","",C15&" | BSR "&B15&" | "&TEXT(D15,"dd-mm-yyyy")&" | ₹"&TEXT(M15,"#,##0")) | T15: =IF($C15="","",SUMIFS('Q1 Data'!$K$4:$K$207,'Q1 Data'!$B$4:$B$207,$S15)+SUMIFS('Q1 Data'!$N$4:$N$207,'Q1 Data'!$B$4:$B$207,$S15)+SUMIFS('Q1 Data'!$L$4:$L$207,'Q1 Data'!$B$4:$B$207,$S15)) | U15: =IF($C15="","",SUMIFS('Q2 Data'!$K$4:$K$207,'Q2 Data'!$B$4:$B$207,$S15)+SUMIFS('Q2 Data'!$N$4:$N$207,'Q2 Data'!$B$4:$B$207,$S15)+SUMIFS('Q2 Data'!$L$4:$L$207,'Q2 Data'!$B$4:$B$207,$S15)) | V15: =IF($C15="","",SUMIFS('Q3 Data'!$K$4:$K$207,'Q3 Data'!$B$4:$B$207,$S15)+SUMIFS('Q3 Data'!$N$4:$N$207,'Q3 Data'!$B$4:$B$207,$S15)+SUMIFS('Q3 Data'!$L$4:$L$207,'Q3 Data'!$B$4:$B$207,$S15)) | W15: =IF($C15="","",SUMIFS('Q4 Data'!$K$4:$K$207,'Q4 Data'!$B$4:$B$207,$S15)+SUMIFS('Q4 Data'!$N$4:$N$207,'Q4 Data'!$B$4:$B$207,$S15)+SUMIFS('Q4 Data'!$L$4:$L$207,'Q4 Data'!$B$4:$B$207,$S15)) | X15: =IF($C15="","",T15+U15+V15+W15) | Y15: =IF($C15="","",M15-L15) | Z15: =IF($C15="","",Y15-X15) | AA15: =IF($C15="","",IF(ROUND(X15-Y15,2)>0,"Over-applied",IF(ROUND(X15-Y15,2)=0,"Fully Utilised","Unconsumed")))
... A207: =IF($C207="","",COUNTIF($C$4:$C207,"<>")) | M207: =IF($C207="","",G207+H207+I207+J207+K207+L207) | S207: =IF($C207="","",C207&" | BSR "&B207&" | "&TEXT(D207,"dd-mm-yyyy")&" | ₹"&TEXT(M207,"#,##0")) | T207: =IF($C207="","",SUMIFS('Q1 Data'!$K$4:$K$207,'Q1 Data'!$B$4:$B$207,$S207)+SUMIFS('Q1 Data'!$N$4:$N$207,'Q1 Data'!$B$4:$B$207,$S207)+SUMIFS('Q1 Data'!$L$4:$L$207,'Q1 Data'!$B$4:$B$207,$S207)) | U207: =IF($C207="","",SUMIFS('Q2 Data'!$K$4:$K$207,'Q2 Data'!$B$4:$B$207,$S207)+SUMIFS('Q2 Data'!$N$4:$N$207,'Q2 Data'!$B$4:$B$207,$S207)+SUMIFS('Q2 Data'!$L$4:$L$207,'Q2 Data'!$B$4:$B$207,$S207)) | V207: =IF($C207="","",SUMIFS('Q3 Data'!$K$4:$K$207,'Q3 Data'!$B$4:$B$207,$S207)+SUMIFS('Q3 Data'!$N$4:$N$207,'Q3 Data'!$B$4:$B$207,$S207)+SUMIFS('Q3 Data'!$L$4:$L$207,'Q3 Data'!$B$4:$B$207,$S207)) | W207: =IF($C207="","",SUMIFS('Q4 Data'!$K$4:$K$207,'Q4 Data'!$B$4:$B$207,$S207)+SUMIFS('Q4 Data'!$N$4:$N$207,'Q4 Data'!$B$4:$B$207,$S207)+SUMIFS('Q4 Data'!$L$4:$L$207,'Q4 Data'!$B$4:$B$207,$S207)) | X207: =IF($C207="","",T207+U207+V207+W207) | Y207: =IF($C207="","",M207-L207) | Z207: =IF($C207="","",Y207-X207) | AA207: =IF($C207="","",IF(ROUND(X207-Y207,2)>0,"Over-applied",IF(ROUND(X207-Y207,2)=0,"Fully Utilised","Unconsumed")))

Sheet Q1 Data
A1: Q1 — pick a Challan for every deductee entry below
A2: =IF(AND(SUMPRODUCT(($C$4:$C$207<>"")*($B$4:$B$207=""))=0,SUMPRODUCT(($C$4:$C$207<>"")*($U$4:$U$207="Over-applied"))=0),"✅ Validation Successful — every entry has a Challan selected, none reference an over-applied challan ("&COUNTIF($C$4:$C$207,"<>")&" entries checked).","❌ VALIDATION FAILED — "&SUMPRODUCT(($C$4:$C$207<>"")*($B$4:$B$207=""))&" entr(y/ies) missing a Challan selection, "&SUMPRODUCT(($C$4:$C$207<>"")*($U$4:$U$207="Over-applied"))&" entr(y/ies) posted against an Over-applied challan. See the pink/red-highlighted row(s) below.")
A3: Sr. No. | B3: Challan (select)* | C3: Deductee Name* | D3: PAN* | E3: PAN Not Available (auto) | F3: Deductee Type (auto) | G3: Section* | H3: Rate of TDS (%) | I3: Date of Payment/Credit* | J3: Amount Paid/Credited (₹)* | K3: TDS Amount (₹) | L3: Surcharge Amount (₹) | M3: Education Cess Amount (₹) | N3: Interest Amount (₹) | O3: Late Fees Amount (₹) | P3: Reason Code | Q3: Lower Deduction Certificate No. | R3: Lower Deduction Rate (%) | S3: Country of Residence | T3: Remarks | U3: Challan Status (ref)
A4: =IF($C4="","",COUNTIF($C$4:$C4,"<>")) | E4: =IF($C4="","",IF(AND(LEN(TRIM(UPPER(D4)))=10,CODE(MID(TRIM(UPPER(D4)),1,1))>=65,CODE(MID(TRIM(UPPER(D4)),1,1))<=90,CODE(MID(TRIM(UPPER(D4)),2,1))>=65,CODE(MID(TRIM(UPPER(D4)),2,1))<=90,CODE(MID(TRIM(UPPER(D4)),3,1))>=65,CODE(MID(TRIM(UPPER(D4)),3,1))<=90,CODE(MID(TRIM(UPPER(D4)),4,1))>=65,CODE(MID(TRIM(UPPER(D4)),4,1))<=90,CODE(MID(TRIM(UPPER(D4)),5,1))>=65,CODE(MID(TRIM(UPPER(D4)),5,1))<=90,CODE(MID(TRIM(UPPER(D4)),10,1))>=65,CODE(MID(TRIM(UPPER(D4)),10,1))<=90,CODE(MID(TRIM(UPPER(D4)),6,1))>=48,CODE(MID(TRIM(UPPER(D4)),6,1))<=57,CODE(MID(TRIM(UPPER(D4)),7,1))>=48,CODE(MID(TRIM(UPPER(D4)),7,1))<=57,CODE(MID(TRIM(UPPER(D4)),8,1))>=48,CODE(MID(TRIM(UPPER(D4)),8,1))<=57,CODE(MID(TRIM(UPPER(D4)),9,1))>=48,CODE(MID(TRIM(UPPER(D4)),9,1))<=57),"N","Y")) | F4: =IF($C4="","",IF(LEN(D4)<4,"",IF(UPPER(MID(D4,4,1))="P","Individual",IF(UPPER(MID(D4,4,1))="H","HUF",IF(UPPER(MID(D4,4,1))="C","Company",IF(UPPER(MID(D4,4,1))="F","Firm",IF(UPPER(MID(D4,4,1))="L","LLP",IF(UPPER(MID(D4,4,1))="T","Trust",IF(UPPER(MID(D4,4,1))="A","AOP",""))))))))) | H4: =IF($C4="","",IF(R4<>"",R4,IF(G4="","",IF(E4="Y",SUMPRODUCT(('Rate Lookup'!$A$1:$A$37=G4)*'Rate Lookup'!$D$1:$D$37),IF(OR(F4="Individual",F4="HUF"),SUMPRODUCT(('Rate Lookup'!$A$1:$A$37=G4)*'Rate Lookup'!$B$1:$B$37),SUMPRODUCT(('Rate Lookup'!$A$1:$A$37=G4)*'Rate Lookup'!$C$1:$C$37))))))) | K4: =IF($C4="","",IF(OR(P4="B",P4="D",P4="E",P4="N",P4="O",P4="P",P4="Q",P4="S",P4="Y",P4="Z"),0,ROUND(J4*H4/100,0))) | L4: =IF($C4="","",0) | M4: =IF($C4="","",0) | N4: =IF($C4="","",IF(OR(K4=0,I4="",IFERROR(INDEX('Challan Master'!$D$4:$D$207,MATCH($B4,'Challan Master'!$S$4:$S$207,0)),"")="",IFERROR(INDEX('Challan Master'!$D$4:$D$207,MATCH($B4,'Challan Master'!$S$4:$S$207,0)),"")<=0),0,IF(IFERROR(INDEX('Challan Master'!$D$4:$D$207,MATCH($B4,'Challan Master'!$S$4:$S$207,0)),"")<=DATE(YEAR(I4),MONTH(I4)+1,7),0,ROUND(K4*0.015*((YEAR(IFERROR(INDEX('Challan Master'!$D$4:$D$207,MATCH($B4,'Challan Master'!$S$4:$S$207,0)),""))-YEAR(I4))*12+(MONTH(IFERROR(INDEX('Challan Master'!$D$4:$D$207,MATCH($B4,'Challan Master'!$S$4:$S$207,0)),""))-MONTH(I4))+1),0)))) | O4: =IF($C4="","",0) | U4: =IF($B4="","",IFERROR(INDEX('Challan Master'!$AA$4:$AA$207,MATCH($B4,'Challan Master'!$S$4:$S$207,0)),""))
A5: =IF($C5="","",COUNTIF($C$4:$C5,"<>")) | E5: =IF($C5="","",IF(AND(LEN(TRIM(UPPER(D5)))=10,CODE(MID(TRIM(UPPER(D5)),1,1))>=65,CODE(MID(TRIM(UPPER(D5)),1,1))<=90,CODE(MID(TRIM(UPPER(D5)),2,1))>=65,CODE(MID(TRIM(UPPER(D5)),2,1))<=90,CODE(MID(TRIM(UPPER(D5)),3,1))>=65,CODE(MID(TRIM(UPPER(D5)),3,1))<=90,CODE(MID(TRIM(UPPER(D5)),4,1))>=65,CODE(MID(TRIM(UPPER(D5)),4,1))<=90,CODE(MID(TRIM(UPPER(D5)),5,1))>=65,CODE(MID(TRIM(UPPER(D5)),5,1))<=90,CODE(MID(TRIM(UPPER(D5)),10,1))>=65,CODE(MID(TRIM(UPPER(D5)),10,1))<=90,CODE(MID(TRIM(UPPER(D5)),6,1))>=48,CODE(MID(TRIM(UPPER(D5)),6,1))<=57,CODE(MID(TRIM(UPPER(D5)),7,1))>=48,CODE(MID(TRIM(UPPER(D5)),7,1))<=57,CODE(MID(TRIM(UPPER(D5)),8,1))>=48,CODE(MID(TRIM(UPPER(D5)),8,1))<=57,CODE(MID(TRIM(UPPER(D5)),9,1))>=48,CODE(MID(TRIM(UPPER(D5)),9,1))<=57),"N","Y")) | F5: =IF($C5="","",IF(LEN(D5)<4,"",IF(UPPER(MID(D5,4,1))="P","Individual",IF(UPPER(MID(D5,4,1))="H","HUF",IF(UPPER(MID(D5,4,1))="C","Company",IF(UPPER(MID(D5,4,1))="F","Firm",IF(UPPER(MID(D5,4,1))="L","LLP",IF(UPPER(MID(D5,4,1))="T","Trust",IF(UPPER(MID(D5,4,1))="A","AOP",""))))))))) | H5: =IF($C5="","",IF(R5<>"",R5,IF(G5="","",IF(E5="Y",SUMPRODUCT(('Rate Lookup'!$A$1:$A$37=G5)*'Rate Lookup'!$D$1:$D$37),IF(OR(F5="Individual",F5="HUF"),SUMPRODUCT(('Rate Lookup'!$A$1:$A$37=G5)*'Rate Lookup'!$B$1:$B$37),SUMPRODUCT(('Rate Lookup'!$A$1:$A$37=G5)*'Rate Lookup'!$C$1:$C$37))))))) | K5: =IF($C5="","",IF(OR(P5="B",P5="D",P5="E",P5="N",P5="O",P5="P",P5="Q",P5="S",P5="Y",P5="Z"),0,ROUND(J5*H5/100,0))) | L5: =IF($C5="","",0) | M5: =IF($C5="","",0) | N5: =IF($C5="","",IF(OR(K5=0,I5="",IFERROR(INDEX('Challan Master'!$D$4:$D$207,MATCH($B5,'Challan Master'!$S$4:$S$207,0)),"")="",IFERROR(INDEX('Challan Master'!$D$4:$D$207,MATCH($B5,'Challan Master'!$S$4:$S$207,0)),"")<=0),0,IF(IFERROR(INDEX('Challan Master'!$D$4:$D$207,MATCH($B5,'Challan Master'!$S$4:$S$207,0)),"")<=DATE(YEAR(I5),MONTH(I5)+1,7),0,ROUND(K5*0.015*((YEAR(IFERROR(INDEX('Challan Master'!$D$4:$D$207,MATCH($B5,'Challan Master'!$S$4:$S$207,0)),""))-YEAR(I5))*12+(MONTH(IFERROR(INDEX('Challan Master'!$D$4:$D$207,MATCH($B5,'Challan Master'!$S$4:$S$207,0)),""))-MONTH(I5))+1),0)))) | O5: =IF($C5="","",0) | U5: =IF($B5="","",IFERROR(INDEX('Challan Master'!$AA$4:$AA$207,MATCH($B5,'Challan Master'!$S$4:$S$207,0)),""))
A6: =IF($C6="","",COUNTIF($C$4:$C6,"<>")) | E6: =IF($C6="","",IF(AND(LEN(TRIM(UPPER(D6)))=10,CODE(MID(TRIM(UPPER(D6)),1,1))>=65,CODE(MID(TRIM(UPPER(D6)),1,1))<=90,CODE(MID(TRIM(UPPER(D6)),2,1))>=65,CODE(MID(TRIM(UPPER(D6)),2,1))<=90,CODE(MID(TRIM(UPPER(D6)),3,1))>=65,CODE(MID(TRIM(UPPER(D6)),3,1))<=90,CODE(MID(TRIM(UPPER(D6)),4,1))>=65,CODE(MID(TRIM(UPPER(D6)),4,1))<=90,CODE(MID(TRIM(UPPER(D6)),5,1))>=65,CODE(MID(TRIM(UPPER(D6)),5,1))<=90,CODE(MID(TRIM(UPPER(D6)),10,1))>=65,CODE(MID(TRIM(UPPER(D6)),10,1))<=90,CODE(MID(TRIM(UPPER(D6)),6,1))>=48,CODE(MID(TRIM(UPPER(D6)),6,1))<=57,CODE(MID(TRIM(UPPER(D6)),7,1))>=48,CODE(MID(TRIM(UPPER(D6)),7,1))<=57,CODE(MID(TRIM(UPPER(D6)),8,1))>=48,CODE(MID(TRIM(UPPER(D6)),8,1))<=57,CODE(MID(TRIM(UPPER(D6)),9,1))>=48,CODE(MID(TRIM(UPPER(D6)),9,1))<=57),"N","Y")) | F6: =IF($C6="","",IF(LEN(D6)<4,"",IF(UPPER(MID(D6,4,1))="P","Individual",IF(UPPER(MID(D6,4,1))="H","HUF",IF(UPPER(MID(D6,4,1))="C","Company",IF(UPPER(MID(D6,4,1))="F","Firm",IF(UPPER(MID(D6,4,1))="L","LLP",IF(UPPER(MID(D6,4,1))="T","Trust",IF(UPPER(MID(D6,4,1))="A","AOP",""))))))))) | H6: =IF($C6="","",IF(R6<>"",R6,IF(G6="","",IF(E6="Y",SUMPRODUCT(('Rate Lookup'!$A$1:$A$37=G6)*'Rate Lookup'!$D$1:$D$37),IF(OR(F6="Individual",F6="HUF"),SUMPRODUCT(('Rate Lookup'!$A$1:$A$37=G6)*'Rate Lookup'!$B$1:$B$37),SUMPRODUCT(('Rate Lookup'!$A$1:$A$37=G6)*'Rate Lookup'!$C$1:$C$37))))))) | K6: =IF($C6="","",IF(OR(P6="B",P6="D",P6="E",P6="N",P6="O",P6="P",P6="Q",P6="S",P6="Y",P6="Z"),0,ROUND(J6*H6/100,0))) | L6: =IF($C6="","",0) | M6: =IF($C6="","",0) | N6: =IF($C6="","",IF(OR(K6=0,I6="",IFERROR(INDEX('Challan Master'!$D$4:$D$207,MATCH($B6,'Challan Master'!$S$4:$S$207,0)),"")="",IFERROR(INDEX('Challan Master'!$D$4:$D$207,MATCH($B6,'Challan Master'!$S$4:$S$207,0)),"")<=0),0,IF(IFERROR(INDEX('Challan Master'!$D$4:$D$207,MATCH($B6,'Challan Master'!$S$4:$S$207,0)),"")<=DATE(YEAR(I6),MONTH(I6)+1,7),0,ROUND(K6*0.015*((YEAR(IFERROR(INDEX('Challan Master'!$D$4:$D$207,MATCH($B6,'Challan Master'!$S$4:$S$207,0)),""))-YEAR(I6))*12+(MONTH(IFERROR(INDEX('Challan Master'!$D$4:$D$207,MATCH($B6,'Challan Master'!$S$4:$S$207,0)),""))-MONTH(I6))+1),0)))) | O6: =IF($C6="","",0) | U6: =IF($B6="","",IFERROR(INDEX('Challan Master'!$AA$4:$AA$207,MATCH($B6,'Challan Master'!$S$4:$S$207,0)),""))
A7: =IF($C7="","",COUNTIF($C$4:$C7,"<>")) | E7: =IF($C7="","",IF(AND(LEN(TRIM(UPPER(D7)))=10,CODE(MID(TRIM(UPPER(D7)),1,1))>=65,CODE(MID(TRIM(UPPER(D7)),1,1))<=90,CODE(MID(TRIM(UPPER(D7)),2,1))>=65,CODE(MID(TRIM(UPPER(D7)),2,1))<=90,CODE(MID(TRIM(UPPER(D7)),3,1))>=65,CODE(MID(TRIM(UPPER(D7)),3,1))<=90,CODE(MID(TRIM(UPPER(D7)),4,1))>=65,CODE(MID(TRIM(UPPER(D7)),4,1))<=90,CODE(MID(TRIM(UPPER(D7)),5,1))>=65,CODE(MID(TRIM(UPPER(D7)),5,1))<=90,CODE(MID(TRIM(UPPER(D7)),10,1))>=65,CODE(MID(TRIM(UPPER(D7)),10,1))<=90,CODE(MID(TRIM(UPPER(D7)),6,1))>=48,CODE(MID(TRIM(UPPER(D7)),6,1))<=57,CODE(MID(TRIM(UPPER(D7)),7,1))>=48,CODE(MID(TRIM(UPPER(D7)),7,1))<=57,CODE(MID(TRIM(UPPER(D7)),8,1))>=48,CODE(MID(TRIM(UPPER(D7)),8,1))<=57,CODE(MID(TRIM(UPPER(D7)),9,1))>=48,CODE(MID(TRIM(UPPER(D7)),9,1))<=57),"N","Y")) | F7: =IF($C7="","",IF(LEN(D7)<4,"",IF(UPPER(MID(D7,4,1))="P","Individual",IF(UPPER(MID(D7,4,1))="H","HUF",IF(UPPER(MID(D7,4,1))="C","Company",IF(UPPER(MID(D7,4,1))="F","Firm",IF(UPPER(MID(D7,4,1))="L","LLP",IF(UPPER(MID(D7,4,1))="T","Trust",IF(UPPER(MID(D7,4,1))="A","AOP",""))))))))) | H7: =IF($C7="","",IF(R7<>"",R7,IF(G7="","",IF(E7="Y",SUMPRODUCT(('Rate Lookup'!$A$1:$A$37=G7)*'Rate Lookup'!$D$1:$D$37),IF(OR(F7="Individual",F7="HUF"),SUMPRODUCT(('Rate Lookup'!$A$1:$A$37=G7)*'Rate Lookup'!$B$1:$B$37),SUMPRODUCT(('Rate Lookup'!$A$1:$A$37=G7)*'Rate Lookup'!$C$1:$C$37))))))) | K7: =IF($C7="","",IF(OR(P7="B",P7="D",P7="E",P7="N",P7="O",P7="P",P7="Q",P7="S",P7="Y",P7="Z"),0,ROUND(J7*H7/100,0))) | L7: =IF($C7="","",0) | M7: =IF($C7="","",0) | N7: =IF($C7="","",IF(OR(K7=0,I7="",IFERROR(INDEX('Challan Master'!$D$4:$D$207,MATCH($B7,'Challan Master'!$S$4:$S$207,0)),"")="",IFERROR(INDEX('Challan Master'!$D$4:$D$207,MATCH($B7,'Challan Master'!$S$4:$S$207,0)),"")<=0),0,IF(IFERROR(INDEX('Challan Master'!$D$4:$D$207,MATCH($B7,'Challan Master'!$S$4:$S$207,0)),"")<=DATE(YEAR(I7),MONTH(I7)+1,7),0,ROUND(K7*0.015*((YEAR(IFERROR(INDEX('Challan Master'!$D$4:$D$207,MATCH($B7,'Challan Master'!$S$4:$S$207,0)),""))-YEAR(I7))*12+(MONTH(IFERROR(INDEX('Challan Master'!$D$4:$D$207,MATCH($B7,'Challan Master'!$S$4:$S$207,0)),""))-MONTH(I7))+1),0)))) | O7: =IF($C7="","",0) | U7: =IF($B7="","",IFERROR(INDEX('Challan Master'!$AA$4:$AA$207,MATCH($B7,'Challan Master'!$S$4:$S$207,0)),""))
A8: =IF($C8="","",COUNTIF($C$4:$C8,"<>")) | E8: =IF($C8="","",IF(AND(LEN(TRIM(UPPER(D8)))=10,CODE(MID(TRIM(UPPER(D8)),1,1))>=65,CODE(MID(TRIM(UPPER(D8)),1,1))<=90,CODE(MID(TRIM(UPPER(D8)),2,1))>=65,CODE(MID(TRIM(UPPER(D8)),2,1))<=90,CODE(MID(TRIM(UPPER(D8)),3,1))>=65,CODE(MID(TRIM(UPPER(D8)),3,1))<=90,CODE(MID(TRIM(UPPER(D8)),4,1))>=65,CODE(MID(TRIM(UPPER(D8)),4,1))<=90,CODE(MID(TRIM(UPPER(D8)),5,1))>=65,CODE(MID(TRIM(UPPER(D8)),5,1))<=90,CODE(MID(TRIM(UPPER(D8)),10,1))>=65,CODE(MID(TRIM(UPPER(D8)),10,1))<=90,CODE(MID(TRIM(UPPER(D8)),6,1))>=48,CODE(MID(TRIM(UPPER(D8)),6,1))<=57,CODE(MID(TRIM(UPPER(D8)),7,1))>=48,CODE(MID(TRIM(UPPER(D8)),7,1))<=57,CODE(MID(TRIM(UPPER(D8)),8,1))>=48,CODE(MID(TRIM(UPPER(D8)),8,1))<=57,CODE(MID(TRIM(UPPER(D8)),9,1))>=48,CODE(MID(TRIM(UPPER(D8)),9,1))<=57),"N","Y")) | F8: =IF($C8="","",IF(LEN(D8)<4,"",IF(UPPER(MID(D8,4,1))="P","Individual",IF(UPPER(MID(D8,4,1))="H","HUF",IF(UPPER(MID(D8,4,1))="C","Company",IF(UPPER(MID(D8,4,1))="F","Firm",IF(UPPER(MID(D8,4,1))="L","LLP",IF(UPPER(MID(D8,4,1))="T","Trust",IF(UPPER(MID(D8,4,1))="A","AOP",""))))))))) | H8: =IF($C8="","",IF(R8<>"",R8,IF(G8="","",IF(E8="Y",SUMPRODUCT(('Rate Lookup'!$A$1:$A$37=G8)*'Rate Lookup'!$D$1:$D$37),IF(OR(F8="Individual",F8="HUF"),SUMPRODUCT(('Rate Lookup'!$A$1:$A$37=G8)*'Rate Lookup'!$B$1:$B$37),SUMPRODUCT(('Rate Lookup'!$A$1:$A$37=G8)*'Rate Lookup'!$C$1:$C$37))))))) | K8: =IF($C8="","",IF(OR(P8="B",P8="D",P8="E",P8="N",P8="O",P8="P",P8="Q",P8="S",P8="Y",P8="Z"),0,ROUND(J8*H8/100,0))) | L8: =IF($C8="","",0) | M8: =IF($C8="","",0) | N8: =IF($C8="","",IF(OR(K8=0,I8="",IFERROR(INDEX('Challan Master'!$D$4:$D$207,MATCH($B8,'Challan Master'!$S$4:$S$207,0)),"")="",IFERROR(INDEX('Challan Master'!$D$4:$D$207,MATCH($B8,'Challan Master'!$S$4:$S$207,0)),"")<=0),0,IF(IFERROR(INDEX('Challan Master'!$D$4:$D$207,MATCH($B8,'Challan Master'!$S$4:$S$207,0)),"")<=DATE(YEAR(I8),MONTH(I8)+1,7),0,ROUND(K8*0.015*((YEAR(IFERROR(INDEX('Challan Master'!$D$4:$D$207,MATCH($B8,'Challan Master'!$S$4:$S$207,0)),""))-YEAR(I8))*12+(MONTH(IFERROR(INDEX('Challan Master'!$D$4:$D$207,MATCH($B8,'Challan Master'!$S$4:$S$207,0)),""))-MONTH(I8))+1),0)))) | O8: =IF($C8="","",0) | U8: =IF($B8="","",IFERROR(INDEX('Challan Master'!$AA$4:$AA$207,MATCH($B8,'Challan Master'!$S$4:$S$207,0)),""))
A9: =IF($C9="","",COUNTIF($C$4:$C9,"<>")) | E9: =IF($C9="","",IF(AND(LEN(TRIM(UPPER(D9)))=10,CODE(MID(TRIM(UPPER(D9)),1,1))>=65,CODE(MID(TRIM(UPPER(D9)),1,1))<=90,CODE(MID(TRIM(UPPER(D9)),2,1))>=65,CODE(MID(TRIM(UPPER(D9)),2,1))<=90,CODE(MID(TRIM(UPPER(D9)),3,1))>=65,CODE(MID(TRIM(UPPER(D9)),3,1))<=90,CODE(MID(TRIM(UPPER(D9)),4,1))>=65,CODE(MID(TRIM(UPPER(D9)),4,1))<=90,CODE(MID(TRIM(UPPER(D9)),5,1))>=65,CODE(MID(TRIM(UPPER(D9)),5,1))<=90,CODE(MID(TRIM(UPPER(D9)),10,1))>=65,CODE(MID(TRIM(UPPER(D9)),10,1))<=90,CODE(MID(TRIM(UPPER(D9)),6,1))>=48,CODE(MID(TRIM(UPPER(D9)),6,1))<=57,CODE(MID(TRIM(UPPER(D9)),7,1))>=48,CODE(MID(TRIM(UPPER(D9)),7,1))<=57,CODE(MID(TRIM(UPPER(D9)),8,1))>=48,CODE(MID(TRIM(UPPER(D9)),8,1))<=57,CODE(MID(TRIM(UPPER(D9)),9,1))>=48,CODE(MID(TRIM(UPPER(D9)),9,1))<=57),"N","Y")) | F9: =IF($C9="","",IF(LEN(D9)<4,"",IF(UPPER(MID(D9,4,1))="P","Individual",IF(UPPER(MID(D9,4,1))="H","HUF",IF(UPPER(MID(D9,4,1))="C","Company",IF(UPPER(MID(D9,4,1))="F","Firm",IF(UPPER(MID(D9,4,1))="L","LLP",IF(UPPER(MID(D9,4,1))="T","Trust",IF(UPPER(MID(D9,4,1))="A","AOP",""))))))))) | H9: =IF($C9="","",IF(R9<>"",R9,IF(G9="","",IF(E9="Y",SUMPRODUCT(('Rate Lookup'!$A$1:$A$37=G9)*'Rate Lookup'!$D$1:$D$37),IF(OR(F9="Individual",F9="HUF"),SUMPRODUCT(('Rate Lookup'!$A$1:$A$37=G9)*'Rate Lookup'!$B$1:$B$37),SUMPRODUCT(('Rate Lookup'!$A$1:$A$37=G9)*'Rate Lookup'!$C$1:$C$37))))))) | K9: =IF($C9="","",IF(OR(P9="B",P9="D",P9="E",P9="N",P9="O",P9="P",P9="Q",P9="S",P9="Y",P9="Z"),0,ROUND(J9*H9/100,0))) | L9: =IF($C9="","",0) | M9: =IF($C9="","",0) | N9: =IF($C9="","",IF(OR(K9=0,I9="",IFERROR(INDEX('Challan Master'!$D$4:$D$207,MATCH($B9,'Challan Master'!$S$4:$S$207,0)),"")="",IFERROR(INDEX('Challan Master'!$D$4:$D$207,MATCH($B9,'Challan Master'!$S$4:$S$207,0)),"")<=0),0,IF(IFERROR(INDEX('Challan Master'!$D$4:$D$207,MATCH($B9,'Challan Master'!$S$4:$S$207,0)),"")<=DATE(YEAR(I9),MONTH(I9)+1,7),0,ROUND(K9*0.015*((YEAR(IFERROR(INDEX('Challan Master'!$D$4:$D$207,MATCH($B9,'Challan Master'!$S$4:$S$207,0)),""))-YEAR(I9))*12+(MONTH(IFERROR(INDEX('Challan Master'!$D$4:$D$207,MATCH($B9,'Challan Master'!$S$4:$S$207,0)),""))-MONTH(I9))+1),0)))) | O9: =IF($C9="","",0) | U9: =IF($B9="","",IFERROR(INDEX('Challan Master'!$AA$4:$AA$207,MATCH($B9,'Challan Master'!$S$4:$S$207,0)),""))
A10: =IF($C10="","",COUNTIF($C$4:$C10,"<>")) | E10: =IF($C10="","",IF(AND(LEN(TRIM(UPPER(D10)))=10,CODE(MID(TRIM(UPPER(D10)),1,1))>=65,CODE(MID(TRIM(UPPER(D10)),1,1))<=90,CODE(MID(TRIM(UPPER(D10)),2,1))>=65,CODE(MID(TRIM(UPPER(D10)),2,1))<=90,CODE(MID(TRIM(UPPER(D10)),3,1))>=65,CODE(MID(TRIM(UPPER(D10)),3,1))<=90,CODE(MID(TRIM(UPPER(D10)),4,1))>=65,CODE(MID(TRIM(UPPER(D10)),4,1))<=90,CODE(MID(TRIM(UPPER(D10)),5,1))>=65,CODE(MID(TRIM(UPPER(D10)),5,1))<=90,CODE(MID(TRIM(UPPER(D10)),10,1))>=65,CODE(MID(TRIM(UPPER(D10)),10,1))<=90,CODE(MID(TRIM(UPPER(D10)),6,1))>=48,CODE(MID(TRIM(UPPER(D10)),6,1))<=57,CODE(MID(TRIM(UPPER(D10)),7,1))>=48,CODE(MID(TRIM(UPPER(D10)),7,1))<=57,CODE(MID(TRIM(UPPER(D10)),8,1))>=48,CODE(MID(TRIM(UPPER(D10)),8,1))<=57,CODE(MID(TRIM(UPPER(D10)),9,1))>=48,CODE(MID(TRIM(UPPER(D10)),9,1))<=57),"N","Y")) | F10: =IF($C10="","",IF(LEN(D10)<4,"",IF(UPPER(MID(D10,4,1))="P","Individual",IF(UPPER(MID(D10,4,1))="H","HUF",IF(UPPER(MID(D10,4,1))="C","Company",IF(UPPER(MID(D10,4,1))="F","Firm",IF(UPPER(MID(D10,4,1))="L","LLP",IF(UPPER(MID(D10,4,1))="T","Trust",IF(UPPER(MID(D10,4,1))="A","AOP",""))))))))) | H10: =IF($C10="","",IF(R10<>"",R10,IF(G10="","",IF(E10="Y",SUMPRODUCT(('Rate Lookup'!$A$1:$A$37=G10)*'Rate Lookup'!$D$1:$D$37),IF(OR(F10="Individual",F10="HUF"),SUMPRODUCT(('Rate Lookup'!$A$1:$A$37=G10)*'Rate Lookup'!$B$1:$B$37),SUMPRODUCT(('Rate Lookup'!$A$1:$A$37=G10)*'Rate Lookup'!$C$1:$C$37))))))) | K10: =IF($C10="","",IF(OR(P10="B",P10="D",P10="E",P10="N",P10="O",P10="P",P10="Q",P10="S",P10="Y",P10="Z"),0,ROUND(J10*H10/100,0))) | L10: =IF($C10="","",0) | M10: =IF($C10="","",0) | N10: =IF($C10="","",IF(OR(K10=0,I10="",IFERROR(INDEX('Challan Master'!$D$4:$D$207,MATCH($B10,'Challan Master'!$S$4:$S$207,0)),"")="",IFERROR(INDEX('Challan Master'!$D$4:$D$207,MATCH($B10,'Challan Master'!$S$4:$S$207,0)),"")<=0),0,IF(IFERROR(INDEX('Challan Master'!$D$4:$D$207,MATCH($B10,'Challan Master'!$S$4:$S$207,0)),"")<=DATE(YEAR(I10),MONTH(I10)+1,7),0,ROUND(K10*0.015*((YEAR(IFERROR(INDEX('Challan Master'!$D$4:$D$207,MATCH($B10,'Challan Master'!$S$4:$S$207,0)),""))-YEAR(I10))*12+(MONTH(IFERROR(INDEX('Challan Master'!$D$4:$D$207,MATCH($B10,'Challan Master'!$S$4:$S$207,0)),""))-MONTH(I10))+1),0)))) | O10: =IF($C10="","",0) | U10: =IF($B10="","",IFERROR(INDEX('Challan Master'!$AA$4:$AA$207,MATCH($B10,'Challan Master'!$S$4:$S$207,0)),""))
A11: =IF($C11="","",COUNTIF($C$4:$C11,"<>")) | E11: =IF($C11="","",IF(AND(LEN(TRIM(UPPER(D11)))=10,CODE(MID(TRIM(UPPER(D11)),1,1))>=65,CODE(MID(TRIM(UPPER(D11)),1,1))<=90,CODE(MID(TRIM(UPPER(D11)),2,1))>=65,CODE(MID(TRIM(UPPER(D11)),2,1))<=90,CODE(MID(TRIM(UPPER(D11)),3,1))>=65,CODE(MID(TRIM(UPPER(D11)),3,1))<=90,CODE(MID(TRIM(UPPER(D11)),4,1))>=65,CODE(MID(TRIM(UPPER(D11)),4,1))<=90,CODE(MID(TRIM(UPPER(D11)),5,1))>=65,CODE(MID(TRIM(UPPER(D11)),5,1))<=90,CODE(MID(TRIM(UPPER(D11)),10,1))>=65,CODE(MID(TRIM(UPPER(D11)),10,1))<=90,CODE(MID(TRIM(UPPER(D11)),6,1))>=48,CODE(MID(TRIM(UPPER(D11)),6,1))<=57,CODE(MID(TRIM(UPPER(D11)),7,1))>=48,CODE(MID(TRIM(UPPER(D11)),7,1))<=57,CODE(MID(TRIM(UPPER(D11)),8,1))>=48,CODE(MID(TRIM(UPPER(D11)),8,1))<=57,CODE(MID(TRIM(UPPER(D11)),9,1))>=48,CODE(MID(TRIM(UPPER(D11)),9,1))<=57),"N","Y")) | F11: =IF($C11="","",IF(LEN(D11)<4,"",IF(UPPER(MID(D11,4,1))="P","Individual",IF(UPPER(MID(D11,4,1))="H","HUF",IF(UPPER(MID(D11,4,1))="C","Company",IF(UPPER(MID(D11,4,1))="F","Firm",IF(UPPER(MID(D11,4,1))="L","LLP",IF(UPPER(MID(D11,4,1))="T","Trust",IF(UPPER(MID(D11,4,1))="A","AOP",""))))))))) | H11: =IF($C11="","",IF(R11<>"",R11,IF(G11="","",IF(E11="Y",SUMPRODUCT(('Rate Lookup'!$A$1:$A$37=G11)*'Rate Lookup'!$D$1:$D$37),IF(OR(F11="Individual",F11="HUF"),SUMPRODUCT(('Rate Lookup'!$A$1:$A$37=G11)*'Rate Lookup'!$B$1:$B$37),SUMPRODUCT(('Rate Lookup'!$A$1:$A$37=G11)*'Rate Lookup'!$C$1:$C$37))))))) | K11: =IF($C11="","",IF(OR(P11="B",P11="D",P11="E",P11="N",P11="O",P11="P",P11="Q",P11="S",P11="Y",P11="Z"),0,ROUND(J11*H11/100,0))) | L11: =IF($C11="","",0) | M11: =IF($C11="","",0) | N11: =IF($C11="","",IF(OR(K11=0,I11="",IFERROR(INDEX('Challan Master'!$D$4:$D$207,MATCH($B11,'Challan Master'!$S$4:$S$207,0)),"")="",IFERROR(INDEX('Challan Master'!$D$4:$D$207,MATCH($B11,'Challan Master'!$S$4:$S$207,0)),"")<=0),0,IF(IFERROR(INDEX('Challan Master'!$D$4:$D$207,MATCH($B11,'Challan Master'!$S$4:$S$207,0)),"")<=DATE(YEAR(I11),MONTH(I11)+1,7),0,ROUND(K11*0.015*((YEAR(IFERROR(INDEX('Challan Master'!$D$4:$D$207,MATCH($B11,'Challan Master'!$S$4:$S$207,0)),""))-YEAR(I11))*12+(MONTH(IFERROR(INDEX('Challan Master'!$D$4:$D$207,MATCH($B11,'Challan Master'!$S$4:$S$207,0)),""))-MONTH(I11))+1),0)))) | O11: =IF($C11="","",0) | U11: =IF($B11="","",IFERROR(INDEX('Challan Master'!$AA$4:$AA$207,MATCH($B11,'Challan Master'!$S$4:$S$207,0)),""))
A12: =IF($C12="","",COUNTIF($C$4:$C12,"<>")) | E12: =IF($C12="","",IF(AND(LEN(TRIM(UPPER(D12)))=10,CODE(MID(TRIM(UPPER(D12)),1,1))>=65,CODE(MID(TRIM(UPPER(D12)),1,1))<=90,CODE(MID(TRIM(UPPER(D12)),2,1))>=65,CODE(MID(TRIM(UPPER(D12)),2,1))<=90,CODE(MID(TRIM(UPPER(D12)),3,1))>=65,CODE(MID(TRIM(UPPER(D12)),3,1))<=90,CODE(MID(TRIM(UPPER(D12)),4,1))>=65,CODE(MID(TRIM(UPPER(D12)),4,1))<=90,CODE(MID(TRIM(UPPER(D12)),5,1))>=65,CODE(MID(TRIM(UPPER(D12)),5,1))<=90,CODE(MID(TRIM(UPPER(D12)),10,1))>=65,CODE(MID(TRIM(UPPER(D12)),10,1))<=90,CODE(MID(TRIM(UPPER(D12)),6,1))>=48,CODE(MID(TRIM(UPPER(D12)),6,1))<=57,CODE(MID(TRIM(UPPER(D12)),7,1))>=48,CODE(MID(TRIM(UPPER(D12)),7,1))<=57,CODE(MID(TRIM(UPPER(D12)),8,1))>=48,CODE(MID(TRIM(UPPER(D12)),8,1))<=57,CODE(MID(TRIM(UPPER(D12)),9,1))>=48,CODE(MID(TRIM(UPPER(D12)),9,1))<=57),"N","Y")) | F12: =IF($C12="","",IF(LEN(D12)<4,"",IF(UPPER(MID(D12,4,1))="P","Individual",IF(UPPER(MID(D12,4,1))="H","HUF",IF(UPPER(MID(D12,4,1))="C","Company",IF(UPPER(MID(D12,4,1))="F","Firm",IF(UPPER(MID(D12,4,1))="L","LLP",IF(UPPER(MID(D12,4,1))="T","Trust",IF(UPPER(MID(D12,4,1))="A","AOP",""))))))))) | H12: =IF($C12="","",IF(R12<>"",R12,IF(G12="","",IF(E12="Y",SUMPRODUCT(('Rate Lookup'!$A$1:$A$37=G12)*'Rate Lookup'!$D$1:$D$37),IF(OR(F12="Individual",F12="HUF"),SUMPRODUCT(('Rate Lookup'!$A$1:$A$37=G12)*'Rate Lookup'!$B$1:$B$37),SUMPRODUCT(('Rate Lookup'!$A$1:$A$37=G12)*'Rate Lookup'!$C$1:$C$37))))))) | K12: =IF($C12="","",IF(OR(P12="B",P12="D",P12="E",P12="N",P12="O",P12="P",P12="Q",P12="S",P12="Y",P12="Z"),0,ROUND(J12*H12/100,0))) | L12: =IF($C12="","",0) | M12: =IF($C12="","",0) | N12: =IF($C12="","",IF(OR(K12=0,I12="",IFERROR(INDEX('Challan Master'!$D$4:$D$207,MATCH($B12,'Challan Master'!$S$4:$S$207,0)),"")="",IFERROR(INDEX('Challan Master'!$D$4:$D$207,MATCH($B12,'Challan Master'!$S$4:$S$207,0)),"")<=0),0,IF(IFERROR(INDEX('Challan Master'!$D$4:$D$207,MATCH($B12,'Challan Master'!$S$4:$S$207,0)),"")<=DATE(YEAR(I12),MONTH(I12)+1,7),0,ROUND(K12*0.015*((YEAR(IFERROR(INDEX('Challan Master'!$D$4:$D$207,MATCH($B12,'Challan Master'!$S$4:$S$207,0)),""))-YEAR(I12))*12+(MONTH(IFERROR(INDEX('Challan Master'!$D$4:$D$207,MATCH($B12,'Challan Master'!$S$4:$S$207,0)),""))-MONTH(I12))+1),0)))) | O12: =IF($C12="","",0) | U12: =IF($B12="","",IFERROR(INDEX('Challan Master'!$AA$4:$AA$207,MATCH($B12,'Challan Master'!$S$4:$S$207,0)),""))
A13: =IF($C13="","",COUNTIF($C$4:$C13,"<>")) | E13: =IF($C13="","",IF(AND(LEN(TRIM(UPPER(D13)))=10,CODE(MID(TRIM(UPPER(D13)),1,1))>=65,CODE(MID(TRIM(UPPER(D13)),1,1))<=90,CODE(MID(TRIM(UPPER(D13)),2,1))>=65,CODE(MID(TRIM(UPPER(D13)),2,1))<=90,CODE(MID(TRIM(UPPER(D13)),3,1))>=65,CODE(MID(TRIM(UPPER(D13)),3,1))<=90,CODE(MID(TRIM(UPPER(D13)),4,1))>=65,CODE(MID(TRIM(UPPER(D13)),4,1))<=90,CODE(MID(TRIM(UPPER(D13)),5,1))>=65,CODE(MID(TRIM(UPPER(D13)),5,1))<=90,CODE(MID(TRIM(UPPER(D13)),10,1))>=65,CODE(MID(TRIM(UPPER(D13)),10,1))<=90,CODE(MID(TRIM(UPPER(D13)),6,1))>=48,CODE(MID(TRIM(UPPER(D13)),6,1))<=57,CODE(MID(TRIM(UPPER(D13)),7,1))>=48,CODE(MID(TRIM(UPPER(D13)),7,1))<=57,CODE(MID(TRIM(UPPER(D13)),8,1))>=48,CODE(MID(TRIM(UPPER(D13)),8,1))<=57,CODE(MID(TRIM(UPPER(D13)),9,1))>=48,CODE(MID(TRIM(UPPER(D13)),9,1))<=57),"N","Y")) | F13: =IF($C13="","",IF(LEN(D13)<4,"",IF(UPPER(MID(D13,4,1))="P","Individual",IF(UPPER(MID(D13,4,1))="H","HUF",IF(UPPER(MID(D13,4,1))="C","Company",IF(UPPER(MID(D13,4,1))="F","Firm",IF(UPPER(MID(D13,4,1))="L","LLP",IF(UPPER(MID(D13,4,1))="T","Trust",IF(UPPER(MID(D13,4,1))="A","AOP",""))))))))) | H13: =IF($C13="","",IF(R13<>"",R13,IF(G13="","",IF(E13="Y",SUMPRODUCT(('Rate Lookup'!$A$1:$A$37=G13)*'Rate Lookup'!$D$1:$D$37),IF(OR(F13="Individual",F13="HUF"),SUMPRODUCT(('Rate Lookup'!$A$1:$A$37=G13)*'Rate Lookup'!$B$1:$B$37),SUMPRODUCT(('Rate Lookup'!$A$1:$A$37=G13)*'Rate Lookup'!$C$1:$C$37))))))) | K13: =IF($C13="","",IF(OR(P13="B",P13="D",P13="E",P13="N",P13="O",P13="P",P13="Q",P13="S",P13="Y",P13="Z"),0,ROUND(J13*H13/100,0))) | L13: =IF($C13="","",0) | M13: =IF($C13="","",0) | N13: =IF($C13="","",IF(OR(K13=0,I13="",IFERROR(INDEX('Challan Master'!$D$4:$D$207,MATCH($B13,'Challan Master'!$S$4:$S$207,0)),"")="",IFERROR(INDEX('Challan Master'!$D$4:$D$207,MATCH($B13,'Challan Master'!$S$4:$S$207,0)),"")<=0),0,IF(IFERROR(INDEX('Challan Master'!$D$4:$D$207,MATCH($B13,'Challan Master'!$S$4:$S$207,0)),"")<=DATE(YEAR(I13),MONTH(I13)+1,7),0,ROUND(K13*0.015*((YEAR(IFERROR(INDEX('Challan Master'!$D$4:$D$207,MATCH($B13,'Challan Master'!$S$4:$S$207,0)),""))-YEAR(I13))*12+(MONTH(IFERROR(INDEX('Challan Master'!$D$4:$D$207,MATCH($B13,'Challan Master'!$S$4:$S$207,0)),""))-MONTH(I13))+1),0)))) | O13: =IF($C13="","",0) | U13: =IF($B13="","",IFERROR(INDEX('Challan Master'!$AA$4:$AA$207,MATCH($B13,'Challan Master'!$S$4:$S$207,0)),""))
A14: =IF($C14="","",COUNTIF($C$4:$C14,"<>")) | E14: =IF($C14="","",IF(AND(LEN(TRIM(UPPER(D14)))=10,CODE(MID(TRIM(UPPER(D14)),1,1))>=65,CODE(MID(TRIM(UPPER(D14)),1,1))<=90,CODE(MID(TRIM(UPPER(D14)),2,1))>=65,CODE(MID(TRIM(UPPER(D14)),2,1))<=90,CODE(MID(TRIM(UPPER(D14)),3,1))>=65,CODE(MID(TRIM(UPPER(D14)),3,1))<=90,CODE(MID(TRIM(UPPER(D14)),4,1))>=65,CODE(MID(TRIM(UPPER(D14)),4,1))<=90,CODE(MID(TRIM(UPPER(D14)),5,1))>=65,CODE(MID(TRIM(UPPER(D14)),5,1))<=90,CODE(MID(TRIM(UPPER(D14)),10,1))>=65,CODE(MID(TRIM(UPPER(D14)),10,1))<=90,CODE(MID(TRIM(UPPER(D14)),6,1))>=48,CODE(MID(TRIM(UPPER(D14)),6,1))<=57,CODE(MID(TRIM(UPPER(D14)),7,1))>=48,CODE(MID(TRIM(UPPER(D14)),7,1))<=57,CODE(MID(TRIM(UPPER(D14)),8,1))>=48,CODE(MID(TRIM(UPPER(D14)),8,1))<=57,CODE(MID(TRIM(UPPER(D14)),9,1))>=48,CODE(MID(TRIM(UPPER(D14)),9,1))<=57),"N","Y")) | F14: =IF($C14="","",IF(LEN(D14)<4,"",IF(UPPER(MID(D14,4,1))="P","Individual",IF(UPPER(MID(D14,4,1))="H","HUF",IF(UPPER(MID(D14,4,1))="C","Company",IF(UPPER(MID(D14,4,1))="F","Firm",IF(UPPER(MID(D14,4,1))="L","LLP",IF(UPPER(MID(D14,4,1))="T","Trust",IF(UPPER(MID(D14,4,1))="A","AOP",""))))))))) | H14: =IF($C14="","",IF(R14<>"",R14,IF(G14="","",IF(E14="Y",SUMPRODUCT(('Rate Lookup'!$A$1:$A$37=G14)*'Rate Lookup'!$D$1:$D$37),IF(OR(F14="Individual",F14="HUF"),SUMPRODUCT(('Rate Lookup'!$A$1:$A$37=G14)*'Rate Lookup'!$B$1:$B$37),SUMPRODUCT(('Rate Lookup'!$A$1:$A$37=G14)*'Rate Lookup'!$C$1:$C$37))))))) | K14: =IF($C14="","",IF(OR(P14="B",P14="D",P14="E",P14="N",P14="O",P14="P",P14="Q",P14="S",P14="Y",P14="Z"),0,ROUND(J14*H14/100,0))) | L14: =IF($C14="","",0) | M14: =IF($C14="","",0) | N14: =IF($C14="","",IF(OR(K14=0,I14="",IFERROR(INDEX('Challan Master'!$D$4:$D$207,MATCH($B14,'Challan Master'!$S$4:$S$207,0)),"")="",IFERROR(INDEX('Challan Master'!$D$4:$D$207,MATCH($B14,'Challan Master'!$S$4:$S$207,0)),"")<=0),0,IF(IFERROR(INDEX('Challan Master'!$D$4:$D$207,MATCH($B14,'Challan Master'!$S$4:$S$207,0)),"")<=DATE(YEAR(I14),MONTH(I14)+1,7),0,ROUND(K14*0.015*((YEAR(IFERROR(INDEX('Challan Master'!$D$4:$D$207,MATCH($B14,'Challan Master'!$S$4:$S$207,0)),""))-YEAR(I14))*12+(MONTH(IFERROR(INDEX('Challan Master'!$D$4:$D$207,MATCH($B14,'Challan Master'!$S$4:$S$207,0)),""))-MONTH(I14))+1),0)))) | O14: =IF($C14="","",0) | U14: =IF($B14="","",IFERROR(INDEX('Challan Master'!$AA$4:$AA$207,MATCH($B14,'Challan Master'!$S$4:$S$207,0)),""))
A15: =IF($C15="","",COUNTIF($C$4:$C15,"<>")) | E15: =IF($C15="","",IF(AND(LEN(TRIM(UPPER(D15)))=10,CODE(MID(TRIM(UPPER(D15)),1,1))>=65,CODE(MID(TRIM(UPPER(D15)),1,1))<=90,CODE(MID(TRIM(UPPER(D15)),2,1))>=65,CODE(MID(TRIM(UPPER(D15)),2,1))<=90,CODE(MID(TRIM(UPPER(D15)),3,1))>=65,CODE(MID(TRIM(UPPER(D15)),3,1))<=90,CODE(MID(TRIM(UPPER(D15)),4,1))>=65,CODE(MID(TRIM(UPPER(D15)),4,1))<=90,CODE(MID(TRIM(UPPER(D15)),5,1))>=65,CODE(MID(TRIM(UPPER(D15)),5,1))<=90,CODE(MID(TRIM(UPPER(D15)),10,1))>=65,CODE(MID(TRIM(UPPER(D15)),10,1))<=90,CODE(MID(TRIM(UPPER(D15)),6,1))>=48,CODE(MID(TRIM(UPPER(D15)),6,1))<=57,CODE(MID(TRIM(UPPER(D15)),7,1))>=48,CODE(MID(TRIM(UPPER(D15)),7,1))<=57,CODE(MID(TRIM(UPPER(D15)),8,1))>=48,CODE(MID(TRIM(UPPER(D15)),8,1))<=57,CODE(MID(TRIM(UPPER(D15)),9,1))>=48,CODE(MID(TRIM(UPPER(D15)),9,1))<=57),"N","Y")) | F15: =IF($C15="","",IF(LEN(D15)<4,"",IF(UPPER(MID(D15,4,1))="P","Individual",IF(UPPER(MID(D15,4,1))="H","HUF",IF(UPPER(MID(D15,4,1))="C","Company",IF(UPPER(MID(D15,4,1))="F","Firm",IF(UPPER(MID(D15,4,1))="L","LLP",IF(UPPER(MID(D15,4,1))="T","Trust",IF(UPPER(MID(D15,4,1))="A","AOP",""))))))))) | H15: =IF($C15="","",IF(R15<>"",R15,IF(G15="","",IF(E15="Y",SUMPRODUCT(('Rate Lookup'!$A$1:$A$37=G15)*'Rate Lookup'!$D$1:$D$37),IF(OR(F15="Individual",F15="HUF"),SUMPRODUCT(('Rate Lookup'!$A$1:$A$37=G15)*'Rate Lookup'!$B$1:$B$37),SUMPRODUCT(('Rate Lookup'!$A$1:$A$37=G15)*'Rate Lookup'!$C$1:$C$37))))))) | K15: =IF($C15="","",IF(OR(P15="B",P15="D",P15="E",P15="N",P15="O",P15="P",P15="Q",P15="S",P15="Y",P15="Z"),0,ROUND(J15*H15/100,0))) | L15: =IF($C15="","",0) | M15: =IF($C15="","",0) | N15: =IF($C15="","",IF(OR(K15=0,I15="",IFERROR(INDEX('Challan Master'!$D$4:$D$207,MATCH($B15,'Challan Master'!$S$4:$S$207,0)),"")="",IFERROR(INDEX('Challan Master'!$D$4:$D$207,MATCH($B15,'Challan Master'!$S$4:$S$207,0)),"")<=0),0,IF(IFERROR(INDEX('Challan Master'!$D$4:$D$207,MATCH($B15,'Challan Master'!$S$4:$S$207,0)),"")<=DATE(YEAR(I15),MONTH(I15)+1,7),0,ROUND(K15*0.015*((YEAR(IFERROR(INDEX('Challan Master'!$D$4:$D$207,MATCH($B15,'Challan Master'!$S$4:$S$207,0)),""))-YEAR(I15))*12+(MONTH(IFERROR(INDEX('Challan Master'!$D$4:$D$207,MATCH($B15,'Challan Master'!$S$4:$S$207,0)),""))-MONTH(I15))+1),0)))) | O15: =IF($C15="","",0) | U15: =IF($B15="","",IFERROR(INDEX('Challan Master'!$AA$4:$AA$207,MATCH($B15,'Challan Master'!$S$4:$S$207,0)),""))
... A207: =IF($C207="","",COUNTIF($C$4:$C207,"<>")) | E207: =IF($C207="","",IF(AND(LEN(TRIM(UPPER(D207)))=10,CODE(MID(TRIM(UPPER(D207)),1,1))>=65,CODE(MID(TRIM(UPPER(D207)),1,1))<=90,CODE(MID(TRIM(UPPER(D207)),2,1))>=65,CODE(MID(TRIM(UPPER(D207)),2,1))<=90,CODE(MID(TRIM(UPPER(D207)),3,1))>=65,CODE(MID(TRIM(UPPER(D207)),3,1))<=90,CODE(MID(TRIM(UPPER(D207)),4,1))>=65,CODE(MID(TRIM(UPPER(D207)),4,1))<=90,CODE(MID(TRIM(UPPER(D207)),5,1))>=65,CODE(MID(TRIM(UPPER(D207)),5,1))<=90,CODE(MID(TRIM(UPPER(D207)),10,1))>=65,CODE(MID(TRIM(UPPER(D207)),10,1))<=90,CODE(MID(TRIM(UPPER(D207)),6,1))>=48,CODE(MID(TRIM(UPPER(D207)),6,1))<=57,CODE(MID(TRIM(UPPER(D207)),7,1))>=48,CODE(MID(TRIM(UPPER(D207)),7,1))<=57,CODE(MID(TRIM(UPPER(D207)),8,1))>=48,CODE(MID(TRIM(UPPER(D207)),8,1))<=57,CODE(MID(TRIM(UPPER(D207)),9,1))>=48,CODE(MID(TRIM(UPPER(D207)),9,1))<=57),"N","Y")) | F207: =IF($C207="","",IF(LEN(D207)<4,"",IF(UPPER(MID(D207,4,1))="P","Individual",IF(UPPER(MID(D207,4,1))="H","HUF",IF(UPPER(MID(D207,4,1))="C","Company",IF(UPPER(MID(D207,4,1))="F","Firm",IF(UPPER(MID(D207,4,1))="L","LLP",IF(UPPER(MID(D207,4,1))="T","Trust",IF(UPPER(MID(D207,4,1))="A","AOP",""))))))))) | H207: =IF($C207="","",IF(R207<>"",R207,IF(G207="","",IF(E207="Y",SUMPRODUCT(('Rate Lookup'!$A$1:$A$37=G207)*'Rate Lookup'!$D$1:$D$37),IF(OR(F207="Individual",F207="HUF"),SUMPRODUCT(('Rate Lookup'!$A$1:$A$37=G207)*'Rate Lookup'!$B$1:$B$37),SUMPRODUCT(('Rate Lookup'!$A$1:$A$37=G207)*'Rate Lookup'!$C$1:$C$37))))))) | K207: =IF($C207="","",IF(OR(P207="B",P207="D",P207="E",P207="N",P207="O",P207="P",P207="Q",P207="S",P207="Y",P207="Z"),0,ROUND(J207*H207/100,0))) | L207: =IF($C207="","",0) | M207: =IF($C207="","",0) | N207: =IF($C207="","",IF(OR(K207=0,I207="",IFERROR(INDEX('Challan Master'!$D$4:$D$207,MATCH($B207,'Challan Master'!$S$4:$S$207,0)),"")="",IFERROR(INDEX('Challan Master'!$D$4:$D$207,MATCH($B207,'Challan Master'!$S$4:$S$207,0)),"")<=0),0,IF(IFERROR(INDEX('Challan Master'!$D$4:$D$207,MATCH($B207,'Challan Master'!$S$4:$S$207,0)),"")<=DATE(YEAR(I207),MONTH(I207)+1,7),0,ROUND(K207*0.015*((YEAR(IFERROR(INDEX('Challan Master'!$D$4:$D$207,MATCH($B207,'Challan Master'!$S$4:$S$207,0)),""))-YEAR(I207))*12+(MONTH(IFERROR(INDEX('Challan Master'!$D$4:$D$207,MATCH($B207,'Challan Master'!$S$4:$S$207,0)),""))-MONTH(I207))+1),0)))) | O207: =IF($C207="","",0) | U207: =IF($B207="","",IFERROR(INDEX('Challan Master'!$AA$4:$AA$207,MATCH($B207,'Challan Master'!$S$4:$S$207,0)),""))

Sheet Q2 Data
A1: Q2 — pick a Challan for every deductee entry below
A2: =IF(AND(SUMPRODUCT(($C$4:$C$207<>"")*($B$4:$B$207=""))=0,SUMPRODUCT(($C$4:$C$207<>"")*($U$4:$U$207="Over-applied"))=0),"✅ Validation Successful — every entry has a Challan selected, none reference an over-applied challan ("&COUNTIF($C$4:$C$207,"<>")&" entries checked).","❌ VALIDATION FAILED — "&SUMPRODUCT(($C$4:$C$207<>"")*($B$4:$B$207=""))&" entr(y/ies) missing a Challan selection, "&SUMPRODUCT(($C$4:$C$207<>"")*($U$4:$U$207="Over-applied"))&" entr(y/ies) posted against an Over-applied challan. See the pink/red-highlighted row(s) below.")
A3: Sr. No. | B3: Challan (select)* | C3: Deductee Name* | D3: PAN* | E3: PAN Not Available (auto) | F3: Deductee Type (auto) | G3: Section* | H3: Rate of TDS (%) | I3: Date of Payment/Credit* | J3: Amount Paid/Credited (₹)* | K3: TDS Amount (₹) | L3: Surcharge Amount (₹) | M3: Education Cess Amount (₹) | N3: Interest Amount (₹) | O3: Late Fees Amount (₹) | P3: Reason Code | Q3: Lower Deduction Certificate No. | R3: Lower Deduction Rate (%) | S3: Country of Residence | T3: Remarks | U3: Challan Status (ref)
A4: =IF($C4="","",COUNTIF($C$4:$C4,"<>")) | E4: =IF($C4="","",IF(AND(LEN(TRIM(UPPER(D4)))=10,CODE(MID(TRIM(UPPER(D4)),1,1))>=65,CODE(MID(TRIM(UPPER(D4)),1,1))<=90,CODE(MID(TRIM(UPPER(D4)),2,1))>=65,CODE(MID(TRIM(UPPER(D4)),2,1))<=90,CODE(MID(TRIM(UPPER(D4)),3,1))>=65,CODE(MID(TRIM(UPPER(D4)),3,1))<=90,CODE(MID(TRIM(UPPER(D4)),4,1))>=65,CODE(MID(TRIM(UPPER(D4)),4,1))<=90,CODE(MID(TRIM(UPPER(D4)),5,1))>=65,CODE(MID(TRIM(UPPER(D4)),5,1))<=90,CODE(MID(TRIM(UPPER(D4)),10,1))>=65,CODE(MID(TRIM(UPPER(D4)),10,1))<=90,CODE(MID(TRIM(UPPER(D4)),6,1))>=48,CODE(MID(TRIM(UPPER(D4)),6,1))<=57,CODE(MID(TRIM(UPPER(D4)),7,1))>=48,CODE(MID(TRIM(UPPER(D4)),7,1))<=57,CODE(MID(TRIM(UPPER(D4)),8,1))>=48,CODE(MID(TRIM(UPPER(D4)),8,1))<=57,CODE(MID(TRIM(UPPER(D4)),9,1))>=48,CODE(MID(TRIM(UPPER(D4)),9,1))<=57),"N","Y")) | F4: =IF($C4="","",IF(LEN(D4)<4,"",IF(UPPER(MID(D4,4,1))="P","Individual",IF(UPPER(MID(D4,4,1))="H","HUF",IF(UPPER(MID(D4,4,1))="C","Company",IF(UPPER(MID(D4,4,1))="F","Firm",IF(UPPER(MID(D4,4,1))="L","LLP",IF(UPPER(MID(D4,4,1))="T","Trust",IF(UPPER(MID(D4,4,1))="A","AOP",""))))))))) | H4: =IF($C4="","",IF(R4<>"",R4,IF(G4="","",IF(E4="Y",SUMPRODUCT(('Rate Lookup'!$A$1:$A$37=G4)*'Rate Lookup'!$D$1:$D$37),IF(OR(F4="Individual",F4="HUF"),SUMPRODUCT(('Rate Lookup'!$A$1:$A$37=G4)*'Rate Lookup'!$B$1:$B$37),SUMPRODUCT(('Rate Lookup'!$A$1:$A$37=G4)*'Rate Lookup'!$C$1:$C$37))))))) | K4: =IF($C4="","",IF(OR(P4="B",P4="D",P4="E",P4="N",P4="O",P4="P",P4="Q",P4="S",P4="Y",P4="Z"),0,ROUND(J4*H4/100,0))) | L4: =IF($C4="","",0) | M4: =IF($C4="","",0) | N4: =IF($C4="","",IF(OR(K4=0,I4="",IFERROR(INDEX('Challan Master'!$D$4:$D$207,MATCH($B4,'Challan Master'!$S$4:$S$207,0)),"")="",IFERROR(INDEX('Challan Master'!$D$4:$D$207,MATCH($B4,'Challan Master'!$S$4:$S$207,0)),"")<=0),0,IF(IFERROR(INDEX('Challan Master'!$D$4:$D$207,MATCH($B4,'Challan Master'!$S$4:$S$207,0)),"")<=DATE(YEAR(I4),MONTH(I4)+1,7),0,ROUND(K4*0.015*((YEAR(IFERROR(INDEX('Challan Master'!$D$4:$D$207,MATCH($B4,'Challan Master'!$S$4:$S$207,0)),""))-YEAR(I4))*12+(MONTH(IFERROR(INDEX('Challan Master'!$D$4:$D$207,MATCH($B4,'Challan Master'!$S$4:$S$207,0)),""))-MONTH(I4))+1),0)))) | O4: =IF($C4="","",0) | U4: =IF($B4="","",IFERROR(INDEX('Challan Master'!$AA$4:$AA$207,MATCH($B4,'Challan Master'!$S$4:$S$207,0)),""))
A5: =IF($C5="","",COUNTIF($C$4:$C5,"<>")) | E5: =IF($C5="","",IF(AND(LEN(TRIM(UPPER(D5)))=10,CODE(MID(TRIM(UPPER(D5)),1,1))>=65,CODE(MID(TRIM(UPPER(D5)),1,1))<=90,CODE(MID(TRIM(UPPER(D5)),2,1))>=65,CODE(MID(TRIM(UPPER(D5)),2,1))<=90,CODE(MID(TRIM(UPPER(D5)),3,1))>=65,CODE(MID(TRIM(UPPER(D5)),3,1))<=90,CODE(MID(TRIM(UPPER(D5)),4,1))>=65,CODE(MID(TRIM(UPPER(D5)),4,1))<=90,CODE(MID(TRIM(UPPER(D5)),5,1))>=65,CODE(MID(TRIM(UPPER(D5)),5,1))<=90,CODE(MID(TRIM(UPPER(D5)),10,1))>=65,CODE(MID(TRIM(UPPER(D5)),10,1))<=90,CODE(MID(TRIM(UPPER(D5)),6,1))>=48,CODE(MID(TRIM(UPPER(D5)),6,1))<=57,CODE(MID(TRIM(UPPER(D5)),7,1))>=48,CODE(MID(TRIM(UPPER(D5)),7,1))<=57,CODE(MID(TRIM(UPPER(D5)),8,1))>=48,CODE(MID(TRIM(UPPER(D5)),8,1))<=57,CODE(MID(TRIM(UPPER(D5)),9,1))>=48,CODE(MID(TRIM(UPPER(D5)),9,1))<=57),"N","Y")) | F5: =IF($C5="","",IF(LEN(D5)<4,"",IF(UPPER(MID(D5,4,1))="P","Individual",IF(UPPER(MID(D5,4,1))="H","HUF",IF(UPPER(MID(D5,4,1))="C","Company",IF(UPPER(MID(D5,4,1))="F","Firm",IF(UPPER(MID(D5,4,1))="L","LLP",IF(UPPER(MID(D5,4,1))="T","Trust",IF(UPPER(MID(D5,4,1))="A","AOP",""))))))))) | H5: =IF($C5="","",IF(R5<>"",R5,IF(G5="","",IF(E5="Y",SUMPRODUCT(('Rate Lookup'!$A$1:$A$37=G5)*'Rate Lookup'!$D$1:$D$37),IF(OR(F5="Individual",F5="HUF"),SUMPRODUCT(('Rate Lookup'!$A$1:$A$37=G5)*'Rate Lookup'!$B$1:$B$37),SUMPRODUCT(('Rate Lookup'!$A$1:$A$37=G5)*'Rate Lookup'!$C$1:$C$37))))))) | K5: =IF($C5="","",IF(OR(P5="B",P5="D",P5="E",P5="N",P5="O",P5="P",P5="Q",P5="S",P5="Y",P5="Z"),0,ROUND(J5*H5/100,0))) | L5: =IF($C5="","",0) | M5: =IF($C5="","",0) | N5: =IF($C5="","",IF(OR(K5=0,I5="",IFERROR(INDEX('Challan Master'!$D$4:$D$207,MATCH($B5,'Challan Master'!$S$4:$S$207,0)),"")="",IFERROR(INDEX('Challan Master'!$D$4:$D$207,MATCH($B5,'Challan Master'!$S$4:$S$207,0)),"")<=0),0,IF(IFERROR(INDEX('Challan Master'!$D$4:$D$207,MATCH($B5,'Challan Master'!$S$4:$S$207,0)),"")<=DATE(YEAR(I5),MONTH(I5)+1,7),0,ROUND(K5*0.015*((YEAR(IFERROR(INDEX('Challan Master'!$D$4:$D$207,MATCH($B5,'Challan Master'!$S$4:$S$207,0)),""))-YEAR(I5))*12+(MONTH(IFERROR(INDEX('Challan Master'!$D$4:$D$207,MATCH($B5,'Challan Master'!$S$4:$S$207,0)),""))-MONTH(I5))+1),0)))) | O5: =IF($C5="","",0) | U5: =IF($B5="","",IFERROR(INDEX('Challan Master'!$AA$4:$AA$207,MATCH($B5,'Challan Master'!$S$4:$S$207,0)),""))
