Workbook

Sheet Instructions
B2: TDS DATA ENTRY TEMPLATE
B3: For client use — please read this sheet fully before entering data
B5: How This Template Works
B6: • | C6: This workbook has THREE sheets: this Instructions sheet, "Challan Details", and "TDS Entries".
B7: • | C7: Fill in "Challan Details" FIRST — one row per TDS challan you have deposited with the bank.
B8: • | C8: Then fill in "TDS Entries" — one row per deductee transaction. Every entry row must reference the Challan ID of the challan it was paid under, using the "Challan ID" dropdown.
B9: • | C9: One Challan can have MANY TDS Entries linked to it. Many entries can share the same Challan ID.
B10: • | C10: Row 4 on both sheets is a WORKED EXAMPLE, shown in gray — delete or overwrite it before submitting; it exists only to show the expected format.
B11: • | C11: Yellow-shaded cells are where you enter data. Green-shaded cells calculate automatically — do not type into them.
B12: • | C12: Do not rename the sheet tabs, insert/delete columns, or change the header row (row 3) on either data sheet — the software matches columns by these exact header names.
B14: Challan Details — Field Guide
B15: Challan ID* | C15: A short, unique code you invent to identify this challan, e.g. CH-001, CH-002. Every TDS Entry links back to one of these. Example: CH-001
B16: BSR Code* | C16: 7-digit bank branch code printed on your challan receipt. Example: 0510002
B17: Challan Serial No.* | C17: The serial number printed on the challan receipt. Example: 24894
B18: Date of Deposit* | C18: The date you deposited this challan with the bank. Must be a real Excel date (use the date picker) — not typed as plain text. Example: 04-06-2026
B19: Total Challan Amount (₹)* | C19: The total amount (TDS + interest, if any) actually deposited via this challan. Example: 5,558
B20: Bank Name | C20: Optional — the bank where the challan was deposited. Example: HDFC Bank
B21: Remarks | C21: Optional — any note you want to keep against this challan.
B22: Total TDS Entries Linked (₹) | C22: Calculates automatically — the sum of TDS + Interest from every TDS Entry row that references this Challan ID. Do not edit. Example: (auto)
B23: Match Status | C23: Calculates automatically — flags whether the linked entries add up to the challan amount, so you can catch data entry errors before submitting. Example: (auto)
B25: TDS Entries — Field Guide
B26: Sr. No. | C26: Calculates automatically once you fill in a row. Do not edit. Example: (auto)
B27: Challan ID* | C27: Pick from the dropdown — must match a Challan ID already entered in "Challan Details". Example: CH-001
B28: Deductee Name* | C28: Full legal name of the person/entity the payment was made to. Example: ABC Traders Pvt. Ltd.
B29: PAN* | C29: 10-character PAN, e.g. 5 letters + 4 digits + 1 letter, in UPPERCASE. No spaces. Example: AACCP6899F
B30: Section* | C30: Pick from the dropdown — the TDS section under which this deduction was made. Example: 194C
B31: Date of Payment/Credit* | C31: The date the deductee was paid or credited (whichever is earlier), as a real Excel date. Example: 31-05-2026
B32: Amount Paid/Credited (₹)* | C32: The gross amount paid or credited to the deductee, before TDS. Example: 55,58,172
B33: Rate of TDS (%)* | C33: The TDS rate applied, as a plain percentage number (e.g. enter 1 for 1%, not 0.01). Example: 0.10
B34: TDS Amount (₹)* | C34: The actual amount of tax deducted. Example: 5,558
B35: Interest (₹) | C35: Interest amount, if any, for late deduction/deposit. Leave blank or 0 if none. Example: 0
B36: Remarks | C36: Optional — any note you want to keep against this entry.
B37: Challan BSR Code | C37: Calculates automatically from the Challan ID you picked. Do not edit. Example: (auto)
B38: Challan Date of Deposit | C38: Calculates automatically from the Challan ID you picked. Do not edit. Example: (auto)
B40: Format Standards (apply throughout)
B41: • | C41: Name: full legal name, avoid abbreviations where possible (e.g. "Private Limited" or "Pvt Ltd" — either is fine, just be consistent).
B42: • | C42: PAN / TAN: uppercase letters and digits only, no spaces or dashes.
B43: • | C43: Dates: use Excel's own date entry (type dd-mm-yyyy or use the calendar picker) — never type a date as a plain sentence or leave it as text.
B44: • | C44: Amounts (₹): plain numbers only — no currency symbols, no commas typed in manually (Excel will display them; typing "₹55,58,172" yourself turns the cell into text and breaks the totals).
B45: • | C45: Percentages (Rate): enter as a plain number, e.g. 10 for 10%, not 0.10.
...

Sheet Challan Details
A1: CHALLAN DETAILS — one row per TDS challan deposited
A2: Row 4 (gray) is a worked example — delete or overwrite before submitting.
A3: Challan ID* | B3: BSR Code* | C3: Challan Serial No.* | D3: Date of Deposit* | E3: Total Challan Amount (₹)* | F3: Bank Name | G3: Remarks | H3: Total TDS Entries Linked (₹) | I3: Match Status
A4: CH-001 | B4: 0510002 | C4: 24894 | D4: 46177 | E4: 5558 | F4: HDFC Bank | G4: Q1 salary TDS | H4: (auto) | I4: (auto)
H5: =SUMIF('TDS Entries'!$B$5:$B$204,A5,'TDS Entries'!$I$5:$I$204)+SUMIF('TDS Entries'!$B$5:$B$204,A5,'TDS Entries'!$J$5:$J$204) | I5: =IF(OR(A5="",H5=0),"",IF(ROUND(E5-H5,2)=0,"Matches","Check Entries"))
H6: =SUMIF('TDS Entries'!$B$5:$B$204,A6,'TDS Entries'!$I$5:$I$204)+SUMIF('TDS Entries'!$B$5:$B$204,A6,'TDS Entries'!$J$5:$J$204) | I6: =IF(OR(A6="",H6=0),"",IF(ROUND(E6-H6,2)=0,"Matches","Check Entries"))
H7: =SUMIF('TDS Entries'!$B$5:$B$204,A7,'TDS Entries'!$I$5:$I$204)+SUMIF('TDS Entries'!$B$5:$B$204,A7,'TDS Entries'!$J$5:$J$204) | I7: =IF(OR(A7="",H7=0),"",IF(ROUND(E7-H7,2)=0,"Matches","Check Entries"))
H8: =SUMIF('TDS Entries'!$B$5:$B$204,A8,'TDS Entries'!$I$5:$I$204)+SUMIF('TDS Entries'!$B$5:$B$204,A8,'TDS Entries'!$J$5:$J$204) | I8: =IF(OR(A8="",H8=0),"",IF(ROUND(E8-H8,2)=0,"Matches","Check Entries"))
H9: =SUMIF('TDS Entries'!$B$5:$B$204,A9,'TDS Entries'!$I$5:$I$204)+SUMIF('TDS Entries'!$B$5:$B$204,A9,'TDS Entries'!$J$5:$J$204) | I9: =IF(OR(A9="",H9=0),"",IF(ROUND(E9-H9,2)=0,"Matches","Check Entries"))
H10: =SUMIF('TDS Entries'!$B$5:$B$204,A10,'TDS Entries'!$I$5:$I$204)+SUMIF('TDS Entries'!$B$5:$B$204,A10,'TDS Entries'!$J$5:$J$204) | I10: =IF(OR(A10="",H10=0),"",IF(ROUND(E10-H10,2)=0,"Matches","Check Entries"))
H11: =SUMIF('TDS Entries'!$B$5:$B$204,A11,'TDS Entries'!$I$5:$I$204)+SUMIF('TDS Entries'!$B$5:$B$204,A11,'TDS Entries'!$J$5:$J$204) | I11: =IF(OR(A11="",H11=0),"",IF(ROUND(E11-H11,2)=0,"Matches","Check Entries"))
H12: =SUMIF('TDS Entries'!$B$5:$B$204,A12,'TDS Entries'!$I$5:$I$204)+SUMIF('TDS Entries'!$B$5:$B$204,A12,'TDS Entries'!$J$5:$J$204) | I12: =IF(OR(A12="",H12=0),"",IF(ROUND(E12-H12,2)=0,"Matches","Check Entries"))
H13: =SUMIF('TDS Entries'!$B$5:$B$204,A13,'TDS Entries'!$I$5:$I$204)+SUMIF('TDS Entries'!$B$5:$B$204,A13,'TDS Entries'!$J$5:$J$204) | I13: =IF(OR(A13="",H13=0),"",IF(ROUND(E13-H13,2)=0,"Matches","Check Entries"))
H14: =SUMIF('TDS Entries'!$B$5:$B$204,A14,'TDS Entries'!$I$5:$I$204)+SUMIF('TDS Entries'!$B$5:$B$204,A14,'TDS Entries'!$J$5:$J$204) | I14: =IF(OR(A14="",H14=0),"",IF(ROUND(E14-H14,2)=0,"Matches","Check Entries"))
H15: =SUMIF('TDS Entries'!$B$5:$B$204,A15,'TDS Entries'!$I$5:$I$204)+SUMIF('TDS Entries'!$B$5:$B$204,A15,'TDS Entries'!$J$5:$J$204) | I15: =IF(OR(A15="",H15=0),"",IF(ROUND(E15-H15,2)=0,"Matches","Check Entries"))
H16: =SUMIF('TDS Entries'!$B$5:$B$204,A16,'TDS Entries'!$I$5:$I$204)+SUMIF('TDS Entries'!$B$5:$B$204,A16,'TDS Entries'!$J$5:$J$204) | I16: =IF(OR(A16="",H16=0),"",IF(ROUND(E16-H16,2)=0,"Matches","Check Entries"))
... H204: =SUMIF('TDS Entries'!$B$5:$B$204,A204,'TDS Entries'!$I$5:$I$204)+SUMIF('TDS Entries'!$B$5:$B$204,A204,'TDS Entries'!$J$5:$J$204) | I204: =IF(OR(A204="",H204=0),"",IF(ROUND(E204-H204,2)=0,"Matches","Check Entries"))

Sheet TDS Entries
A1: TDS ENTRIES — one row per deductee transaction, linked to a Challan ID above
A2: Row 4 (gray) is a worked example — delete or overwrite before submitting.
A3: Sr. No. | B3: Challan ID* | C3: Deductee Name* | D3: PAN* | E3: Section* | F3: Date of Payment/Credit* | G3: Amount Paid/Credited (₹)* | H3: Rate of TDS (%)* | I3: TDS Amount (₹)* | J3: Interest (₹) | K3: Remarks | L3: Challan BSR Code | M3: Challan Date of Deposit
A4: =IF(C4="","",ROW()-3) | B4: CH-001 | C4: ADINATH PROCESSING INDUSTRIES PRIVATE LIMITED | D4: AACCP6899F | E4: 194C | F4: 46173 | G4: 5558172 | H4: 0.1 | I4: 5558 | J4: 0 | L4: =IFERROR(INDEX('Challan Details'!$B$5:$B$204,MATCH(B4,'Challan Details'!$A$5:$A$204,0)),"") | M4: =IFERROR(INDEX('Challan Details'!$D$5:$D$204,MATCH(B4,'Challan Details'!$A$5:$A$204,0)),"")
A5: =IF(C5="","",ROW()-3) | L5: =IFERROR(INDEX('Challan Details'!$B$5:$B$204,MATCH(B5,'Challan Details'!$A$5:$A$204,0)),"") | M5: =IFERROR(INDEX('Challan Details'!$D$5:$D$204,MATCH(B5,'Challan Details'!$A$5:$A$204,0)),"")
A6: =IF(C6="","",ROW()-3) | L6: =IFERROR(INDEX('Challan Details'!$B$5:$B$204,MATCH(B6,'Challan Details'!$A$5:$A$204,0)),"") | M6: =IFERROR(INDEX('Challan Details'!$D$5:$D$204,MATCH(B6,'Challan Details'!$A$5:$A$204,0)),"")
A7: =IF(C7="","",ROW()-3) | L7: =IFERROR(INDEX('Challan Details'!$B$5:$B$204,MATCH(B7,'Challan Details'!$A$5:$A$204,0)),"") | M7: =IFERROR(INDEX('Challan Details'!$D$5:$D$204,MATCH(B7,'Challan Details'!$A$5:$A$204,0)),"")
A8: =IF(C8="","",ROW()-3) | L8: =IFERROR(INDEX('Challan Details'!$B$5:$B$204,MATCH(B8,'Challan Details'!$A$5:$A$204,0)),"") | M8: =IFERROR(INDEX('Challan Details'!$D$5:$D$204,MATCH(B8,'Challan Details'!$A$5:$A$204,0)),"")
A9: =IF(C9="","",ROW()-3) | L9: =IFERROR(INDEX('Challan Details'!$B$5:$B$204,MATCH(B9,'Challan Details'!$A$5:$A$204,0)),"") | M9: =IFERROR(INDEX('Challan Details'!$D$5:$D$204,MATCH(B9,'Challan Details'!$A$5:$A$204,0)),"")
A10: =IF(C10="","",ROW()-3) | L10: =IFERROR(INDEX('Challan Details'!$B$5:$B$204,MATCH(B10,'Challan Details'!$A$5:$A$204,0)),"") | M10: =IFERROR(INDEX('Challan Details'!$D$5:$D$204,MATCH(B10,'Challan Details'!$A$5:$A$204,0)),"")
A11: =IF(C11="","",ROW()-3) | L11: =IFERROR(INDEX('Challan Details'!$B$5:$B$204,MATCH(B11,'Challan Details'!$A$5:$A$204,0)),"") | M11: =IFERROR(INDEX('Challan Details'!$D$5:$D$204,MATCH(B11,'Challan Details'!$A$5:$A$204,0)),"")
A12: =IF(C12="","",ROW()-3) | L12: =IFERROR(INDEX('Challan Details'!$B$5:$B$204,MATCH(B12,'Challan Details'!$A$5:$A$204,0)),"") | M12: =IFERROR(INDEX('Challan Details'!$D$5:$D$204,MATCH(B12,'Challan Details'!$A$5:$A$204,0)),"")
A13: =IF(C13="","",ROW()-3) | L13: =IFERROR(INDEX('Challan Details'!$B$5:$B$204,MATCH(B13,'Challan Details'!$A$5:$A$204,0)),"") | M13: =IFERROR(INDEX('Challan Details'!$D$5:$D$204,MATCH(B13,'Challan Details'!$A$5:$A$204,0)),"")
A14: =IF(C14="","",ROW()-3) | L14: =IFERROR(INDEX('Challan Details'!$B$5:$B$204,MATCH(B14,'Challan Details'!$A$5:$A$204,0)),"") | M14: =IFERROR(INDEX('Challan Details'!$D$5:$D$204,MATCH(B14,'Challan Details'!$A$5:$A$204,0)),"")
A15: =IF(C15="","",ROW()-3) | L15: =IFERROR(INDEX('Challan Details'!$B$5:$B$204,MATCH(B15,'Challan Details'!$A$5:$A$204,0)),"") | M15: =IFERROR(INDEX('Challan Details'!$D$5:$D$204,MATCH(B15,'Challan Details'!$A$5:$A$204,0)),"")
A16: =IF(C16="","",ROW()-3) | L16: =IFERROR(INDEX('Challan Details'!$B$5:$B$204,MATCH(B16,'Challan Details'!$A$5:$A$204,0)),"") | M16: =IFERROR(INDEX('Challan Details'!$D$5:$D$204,MATCH(B16,'Challan Details'!$A$5:$A$204,0)),"")
... A204: =IF(C204="","",ROW()-3) | L204: =IFERROR(INDEX('Challan Details'!$B$5:$B$204,MATCH(B204,'Challan Details'!$A$5:$A$204,0)),"") | M204: =IFERROR(INDEX('Challan Details'!$D$5:$D$204,MATCH(B204,'Challan Details'!$A$5:$A$204,0)),"")
